{
    "inputs": {
        "dependency": "tensorflow",
        "outfile": "/home/vanessa/Desktop/Code/caliper-analysis/.caliper/pypi-tensorflow-1.13.0rc0-python-cp34.json",
        "dockerfile": "FROM python:3.4\nADD . /tmp/repo\nWORKDIR /tmp/repo\nENV LANG C.UTF-8\nENV SHELL /bin/bash\nRUN apt-get update && apt-get install -y wget ca-certificates gnupg2 git\nRUN /bin/bash -c \"wget https://files.pythonhosted.org/packages/c3/7a/a05da5b1e972df83458996bf88333f97543986339ec1dd5299b70845708e/tensorflow-1.13.0rc0-cp34-cp34m-manylinux1_x86_64.whl && pip install tensorflow-1.13.0rc0-cp34-cp34m-manylinux1_x86_64.whl\"\n",
        "force": false,
        "exists": true,
        "name": "pypi-tensorflow-1.13.0rc0-python-cp34",
        "tests": "tensorflow_v0.11/5_MultiGPU/multigpu_basics.py\ntensorflow_v0.11/1_Introduction/basic_operations.py\ntensorflow_v0.11/1_Introduction/helloworld.py\ntensorflow_v0.11/4_Utils/tensorboard_advanced.py\ntensorflow_v0.11/4_Utils/tensorboard_basic.py\ntensorflow_v0.11/2_BasicModels/logistic_regression.py\ntensorflow_v0.11/2_BasicModels/linear_regression.py\ntensorflow_v0.11/2_BasicModels/nearest_neighbor.py\ntensorflow_v0.11/3_NeuralNetworks/bidirectional_rnn.py\ntensorflow_v0.11/3_NeuralNetworks/autoencoder.py\ntensorflow_v0.11/3_NeuralNetworks/recurrent_network.py\ntensorflow_v0.11/3_NeuralNetworks/dynamic_rnn.py\ntensorflow_v0.11/3_NeuralNetworks/multilayer_perceptron.py\ntensorflow_v0.11/3_NeuralNetworks/convolutional_network.py\ntensorflow_v1/1_Introduction/basic_eager_api.py\ntensorflow_v1/1_Introduction/basic_operations.py\ntensorflow_v1/1_Introduction/helloworld.py\ntensorflow_v1/4_Utils/tensorboard_advanced.py\ntensorflow_v1/4_Utils/tensorboard_basic.py\ntensorflow_v1/5_DataManagement/build_an_image_dataset.py\ntensorflow_v1/5_DataManagement/tensorflow_dataset_api.py\ntensorflow_v1/2_BasicModels/random_forest.py\ntensorflow_v1/2_BasicModels/gradient_boosted_decision_tree.py\ntensorflow_v1/2_BasicModels/logistic_regression.py\ntensorflow_v1/2_BasicModels/word2vec.py\ntensorflow_v1/2_BasicModels/linear_regression.py\ntensorflow_v1/2_BasicModels/logistic_regression_eager_api.py\ntensorflow_v1/2_BasicModels/nearest_neighbor.py\ntensorflow_v1/2_BasicModels/linear_regression_eager_api.py\ntensorflow_v1/2_BasicModels/kmeans.py\ntensorflow_v1/6_MultiGPU/multigpu_basics.py\ntensorflow_v1/6_MultiGPU/multigpu_cnn.py\ntensorflow_v1/3_NeuralNetworks/variational_autoencoder.py\ntensorflow_v1/3_NeuralNetworks/neural_network_eager_api.py\ntensorflow_v1/3_NeuralNetworks/neural_network.py\ntensorflow_v1/3_NeuralNetworks/bidirectional_rnn.py\ntensorflow_v1/3_NeuralNetworks/convolutional_network_raw.py\ntensorflow_v1/3_NeuralNetworks/autoencoder.py\ntensorflow_v1/3_NeuralNetworks/gan.py\ntensorflow_v1/3_NeuralNetworks/recurrent_network.py\ntensorflow_v1/3_NeuralNetworks/neural_network_raw.py\ntensorflow_v1/3_NeuralNetworks/multilayer_perceptron.py\ntensorflow_v1/3_NeuralNetworks/convolutional_network.py",
        "cleanup": true,
        "outdir": "/home/vanessa/Desktop/Code/caliper-analysis"
    },
    "tests": {
        "build": {
            "retval": 0
        },
        "tensorflow_v0.11/5_MultiGPU/multigpu_basics.py": {
            "error": [
                "2021-01-07 02:18:17.004430: I tensorflow/core/platform/cpu_feature_guard.cc:141] Your CPU supports instructions that this TensorFlow binary was not compiled to use: AVX2 FMA\n",
                "2021-01-07 02:18:17.026067: I tensorflow/core/platform/profile_utils/cpu_utils.cc:94] CPU Frequency: 1999965000 Hz\n",
                "2021-01-07 02:18:17.026386: I tensorflow/compiler/xla/service/service.cc:150] XLA service 0x5636106125d0 executing computations on platform Host. Devices:\n",
                "2021-01-07 02:18:17.026403: I tensorflow/compiler/xla/service/service.cc:158]   StreamExecutor device (0): <undefined>, <undefined>\n",
                "2021-01-07 02:18:17.026623: I tensorflow/core/common_runtime/direct_session.cc:317] Device mapping:\n",
                "/job:localhost/replica:0/task:0/device:XLA_CPU:0 -> device: XLA_CPU device\n",
                "\n",
                "2021-01-07 02:18:17.027660: I tensorflow/core/common_runtime/placer.cc:1059] MatMul: (MatMul)/job:localhost/replica:0/task:0/device:CPU:0\n",
                "2021-01-07 02:18:17.027679: I tensorflow/core/common_runtime/placer.cc:1059] MatMul_1: (MatMul)/job:localhost/replica:0/task:0/device:CPU:0\n",
                "2021-01-07 02:18:17.027686: I tensorflow/core/common_runtime/placer.cc:1059] AddN: (AddN)/job:localhost/replica:0/task:0/device:CPU:0\n",
                "2021-01-07 02:18:17.027692: I tensorflow/core/common_runtime/placer.cc:1059] Placeholder: (Placeholder)/job:localhost/replica:0/task:0/device:CPU:0\n",
                "2021-01-07 02:18:17.027699: I tensorflow/core/common_runtime/placer.cc:1059] Placeholder_1: (Placeholder)/job:localhost/replica:0/task:0/device:CPU:0\n",
                "2021-01-07 02:18:17.058277: I tensorflow/core/common_runtime/direct_session.cc:317] Device mapping:\n",
                "/job:localhost/replica:0/task:0/device:XLA_CPU:0 -> device: XLA_CPU device\n",
                "\n",
                "2021-01-07 02:18:17.058919: I tensorflow/core/common_runtime/placer.cc:1059] MatMul: (MatMul)/job:localhost/replica:0/task:0/device:CPU:0\n",
                "2021-01-07 02:18:17.058936: I tensorflow/core/common_runtime/placer.cc:1059] MatMul_1: (MatMul)/job:localhost/replica:0/task:0/device:CPU:0\n",
                "2021-01-07 02:18:17.058942: I tensorflow/core/common_runtime/placer.cc:1059] AddN: (AddN)/job:localhost/replica:0/task:0/device:CPU:0\n",
                "2021-01-07 02:18:17.058947: I tensorflow/core/common_runtime/placer.cc:1059] MatMul_2: (MatMul)/job:localhost/replica:0/task:0/device:CPU:0\n",
                "2021-01-07 02:18:17.058952: I tensorflow/core/common_runtime/placer.cc:1059] MatMul_3: (MatMul)/job:localhost/replica:0/task:0/device:CPU:0\n",
                "2021-01-07 02:18:17.058956: I tensorflow/core/common_runtime/placer.cc:1059] AddN_1: (AddN)/job:localhost/replica:0/task:0/device:CPU:0\n",
                "2021-01-07 02:18:17.058961: I tensorflow/core/common_runtime/placer.cc:1059] Placeholder: (Placeholder)/job:localhost/replica:0/task:0/device:CPU:0\n",
                "2021-01-07 02:18:17.058966: I tensorflow/core/common_runtime/placer.cc:1059] Placeholder_1: (Placeholder)/job:localhost/replica:0/task:0/device:CPU:0\n",
                "2021-01-07 02:18:17.058971: I tensorflow/core/common_runtime/placer.cc:1059] Placeholder_2: (Placeholder)/job:localhost/replica:0/task:0/device:CPU:0\n",
                "2021-01-07 02:18:17.058978: I tensorflow/core/common_runtime/placer.cc:1059] Placeholder_3: (Placeholder)/job:localhost/replica:0/task:0/device:CPU:0\n"
            ],
            "output": [
                "Single CPU computation time: 0:00:00.049007\n",
                "Multi CPU computation time: 0:00:00.027068\n",
                "Device mapping:\n",
                "/job:localhost/replica:0/task:0/device:XLA_CPU:0 -> device: XLA_CPU device\n",
                "MatMul: (MatMul): /job:localhost/replica:0/task:0/device:CPU:0\n",
                "MatMul_1: (MatMul): /job:localhost/replica:0/task:0/device:CPU:0\n",
                "AddN: (AddN): /job:localhost/replica:0/task:0/device:CPU:0\n",
                "Placeholder: (Placeholder): /job:localhost/replica:0/task:0/device:CPU:0\n",
                "Placeholder_1: (Placeholder): /job:localhost/replica:0/task:0/device:CPU:0\n",
                "Device mapping:\n",
                "/job:localhost/replica:0/task:0/device:XLA_CPU:0 -> device: XLA_CPU device\n",
                "MatMul: (MatMul): /job:localhost/replica:0/task:0/device:CPU:0\n",
                "MatMul_1: (MatMul): /job:localhost/replica:0/task:0/device:CPU:0\n",
                "AddN: (AddN): /job:localhost/replica:0/task:0/device:CPU:0\n",
                "MatMul_2: (MatMul): /job:localhost/replica:0/task:0/device:CPU:0\n",
                "MatMul_3: (MatMul): /job:localhost/replica:0/task:0/device:CPU:0\n",
                "AddN_1: (AddN): /job:localhost/replica:0/task:0/device:CPU:0\n",
                "Placeholder: (Placeholder): /job:localhost/replica:0/task:0/device:CPU:0\n",
                "Placeholder_1: (Placeholder): /job:localhost/replica:0/task:0/device:CPU:0\n",
                "Placeholder_2: (Placeholder): /job:localhost/replica:0/task:0/device:CPU:0\n",
                "Placeholder_3: (Placeholder): /job:localhost/replica:0/task:0/device:CPU:0\n"
            ],
            "retval": 0,
            "seconds": 2.03
        },
        "tensorflow_v0.11/1_Introduction/basic_operations.py": {
            "error": [
                "2021-01-07 02:18:19.014581: I tensorflow/core/platform/cpu_feature_guard.cc:141] Your CPU supports instructions that this TensorFlow binary was not compiled to use: AVX2 FMA\n",
                "2021-01-07 02:18:19.042126: I tensorflow/core/platform/profile_utils/cpu_utils.cc:94] CPU Frequency: 1999965000 Hz\n",
                "2021-01-07 02:18:19.042481: I tensorflow/compiler/xla/service/service.cc:150] XLA service 0x55809038c6f0 executing computations on platform Host. Devices:\n",
                "2021-01-07 02:18:19.042501: I tensorflow/compiler/xla/service/service.cc:158]   StreamExecutor device (0): <undefined>, <undefined>\n"
            ],
            "output": [
                "a=2, b=3\n",
                "Addition with constants: 5\n",
                "Multiplication with constants: 6\n",
                "Addition with variables: 5\n",
                "Multiplication with variables: 6\n",
                "[[12.]]\n"
            ],
            "retval": 0,
            "seconds": 1.94
        },
        "tensorflow_v0.11/1_Introduction/helloworld.py": {
            "error": [
                "2021-01-07 02:18:20.913213: I tensorflow/core/platform/cpu_feature_guard.cc:141] Your CPU supports instructions that this TensorFlow binary was not compiled to use: AVX2 FMA\n",
                "2021-01-07 02:18:20.934247: I tensorflow/core/platform/profile_utils/cpu_utils.cc:94] CPU Frequency: 1999965000 Hz\n",
                "2021-01-07 02:18:20.934667: I tensorflow/compiler/xla/service/service.cc:150] XLA service 0x5559d214a0e0 executing computations on platform Host. Devices:\n",
                "2021-01-07 02:18:20.934707: I tensorflow/compiler/xla/service/service.cc:158]   StreamExecutor device (0): <undefined>, <undefined>\n"
            ],
            "output": [
                "b'Hello, TensorFlow!'\n"
            ],
            "retval": 0,
            "seconds": 1.87
        },
        "tensorflow_v0.11/4_Utils/tensorboard_advanced.py": {
            "error": [
                "Traceback (most recent call last):\n",
                "  File \"tensorflow_v0.11/4_Utils/tensorboard_advanced.py\", line 21, in <module>\n",
                "    from tensorflow.examples.tutorials.mnist import input_data\n",
                "  File \"/usr/local/lib/python3.4/site-packages/tensorflow/examples/tutorials/mnist/__init__.py\", line 21, in <module>\n",
                "    from tensorflow.examples.tutorials.mnist import input_data\n",
                "  File \"/usr/local/lib/python3.4/site-packages/tensorflow/examples/tutorials/mnist/input_data.py\", line 30, in <module>\n",
                "    from tensorflow.contrib.learn.python.learn.datasets.mnist import read_data_sets\n",
                "  File \"/usr/local/lib/python3.4/site-packages/tensorflow/contrib/__init__.py\", line 40, in <module>\n",
                "    from tensorflow.contrib import distribute\n",
                "  File \"/usr/local/lib/python3.4/site-packages/tensorflow/contrib/distribute/__init__.py\", line 33, in <module>\n",
                "    from tensorflow.contrib.distribute.python.tpu_strategy import TPUStrategy\n",
                "  File \"/usr/local/lib/python3.4/site-packages/tensorflow/contrib/distribute/python/tpu_strategy.py\", line 27, in <module>\n",
                "    from tensorflow.contrib.tpu.python.ops import tpu_ops\n",
                "  File \"/usr/local/lib/python3.4/site-packages/tensorflow/contrib/tpu/__init__.py\", line 73, in <module>\n",
                "    from tensorflow.contrib.tpu.python.tpu.keras_support import tpu_model as keras_to_tpu_model\n",
                "  File \"/usr/local/lib/python3.4/site-packages/tensorflow/contrib/tpu/python/tpu/keras_support.py\", line 62, in <module>\n",
                "    from tensorflow.contrib.tpu.python.tpu import tpu\n",
                "  File \"/usr/local/lib/python3.4/site-packages/tensorflow/contrib/tpu/python/tpu/tpu.py\", line 24, in <module>\n",
                "    from tensorflow.contrib.compiler import xla\n",
                "  File \"/usr/local/lib/python3.4/site-packages/tensorflow/contrib/compiler/xla.py\", line 28, in <module>\n",
                "    from tensorflow.python.estimator import model_fn as model_fn_lib\n",
                "  File \"/usr/local/lib/python3.4/site-packages/tensorflow/python/estimator/model_fn.py\", line 26, in <module>\n",
                "    from tensorflow_estimator.python.estimator import model_fn\n",
                "  File \"/usr/local/lib/python3.4/site-packages/tensorflow_estimator/python/estimator/model_fn.py\", line 27, in <module>\n",
                "    from tensorflow.python.saved_model import model_utils as export_utils\n",
                "ImportError: cannot import name 'model_utils'\n"
            ],
            "output": [],
            "retval": 1,
            "seconds": 2.19
        },
        "tensorflow_v0.11/4_Utils/tensorboard_basic.py": {
            "error": [
                "Traceback (most recent call last):\n",
                "  File \"tensorflow_v0.11/4_Utils/tensorboard_basic.py\", line 21, in <module>\n",
                "    from tensorflow.examples.tutorials.mnist import input_data\n",
                "  File \"/usr/local/lib/python3.4/site-packages/tensorflow/examples/tutorials/mnist/__init__.py\", line 21, in <module>\n",
                "    from tensorflow.examples.tutorials.mnist import input_data\n",
                "  File \"/usr/local/lib/python3.4/site-packages/tensorflow/examples/tutorials/mnist/input_data.py\", line 30, in <module>\n",
                "    from tensorflow.contrib.learn.python.learn.datasets.mnist import read_data_sets\n",
                "  File \"/usr/local/lib/python3.4/site-packages/tensorflow/contrib/__init__.py\", line 40, in <module>\n",
                "    from tensorflow.contrib import distribute\n",
                "  File \"/usr/local/lib/python3.4/site-packages/tensorflow/contrib/distribute/__init__.py\", line 33, in <module>\n",
                "    from tensorflow.contrib.distribute.python.tpu_strategy import TPUStrategy\n",
                "  File \"/usr/local/lib/python3.4/site-packages/tensorflow/contrib/distribute/python/tpu_strategy.py\", line 27, in <module>\n",
                "    from tensorflow.contrib.tpu.python.ops import tpu_ops\n",
                "  File \"/usr/local/lib/python3.4/site-packages/tensorflow/contrib/tpu/__init__.py\", line 73, in <module>\n",
                "    from tensorflow.contrib.tpu.python.tpu.keras_support import tpu_model as keras_to_tpu_model\n",
                "  File \"/usr/local/lib/python3.4/site-packages/tensorflow/contrib/tpu/python/tpu/keras_support.py\", line 62, in <module>\n",
                "    from tensorflow.contrib.tpu.python.tpu import tpu\n",
                "  File \"/usr/local/lib/python3.4/site-packages/tensorflow/contrib/tpu/python/tpu/tpu.py\", line 24, in <module>\n",
                "    from tensorflow.contrib.compiler import xla\n",
                "  File \"/usr/local/lib/python3.4/site-packages/tensorflow/contrib/compiler/xla.py\", line 28, in <module>\n",
                "    from tensorflow.python.estimator import model_fn as model_fn_lib\n",
                "  File \"/usr/local/lib/python3.4/site-packages/tensorflow/python/estimator/model_fn.py\", line 26, in <module>\n",
                "    from tensorflow_estimator.python.estimator import model_fn\n",
                "  File \"/usr/local/lib/python3.4/site-packages/tensorflow_estimator/python/estimator/model_fn.py\", line 27, in <module>\n",
                "    from tensorflow.python.saved_model import model_utils as export_utils\n",
                "ImportError: cannot import name 'model_utils'\n"
            ],
            "output": [],
            "retval": 1,
            "seconds": 1.96
        },
        "tensorflow_v0.11/2_BasicModels/logistic_regression.py": {
            "error": [
                "Traceback (most recent call last):\n",
                "  File \"tensorflow_v0.11/2_BasicModels/logistic_regression.py\", line 21, in <module>\n",
                "    from tensorflow.examples.tutorials.mnist import input_data\n",
                "  File \"/usr/local/lib/python3.4/site-packages/tensorflow/examples/tutorials/mnist/__init__.py\", line 21, in <module>\n",
                "    from tensorflow.examples.tutorials.mnist import input_data\n",
                "  File \"/usr/local/lib/python3.4/site-packages/tensorflow/examples/tutorials/mnist/input_data.py\", line 30, in <module>\n",
                "    from tensorflow.contrib.learn.python.learn.datasets.mnist import read_data_sets\n",
                "  File \"/usr/local/lib/python3.4/site-packages/tensorflow/contrib/__init__.py\", line 40, in <module>\n",
                "    from tensorflow.contrib import distribute\n",
                "  File \"/usr/local/lib/python3.4/site-packages/tensorflow/contrib/distribute/__init__.py\", line 33, in <module>\n",
                "    from tensorflow.contrib.distribute.python.tpu_strategy import TPUStrategy\n",
                "  File \"/usr/local/lib/python3.4/site-packages/tensorflow/contrib/distribute/python/tpu_strategy.py\", line 27, in <module>\n",
                "    from tensorflow.contrib.tpu.python.ops import tpu_ops\n",
                "  File \"/usr/local/lib/python3.4/site-packages/tensorflow/contrib/tpu/__init__.py\", line 73, in <module>\n",
                "    from tensorflow.contrib.tpu.python.tpu.keras_support import tpu_model as keras_to_tpu_model\n",
                "  File \"/usr/local/lib/python3.4/site-packages/tensorflow/contrib/tpu/python/tpu/keras_support.py\", line 62, in <module>\n",
                "    from tensorflow.contrib.tpu.python.tpu import tpu\n",
                "  File \"/usr/local/lib/python3.4/site-packages/tensorflow/contrib/tpu/python/tpu/tpu.py\", line 24, in <module>\n",
                "    from tensorflow.contrib.compiler import xla\n",
                "  File \"/usr/local/lib/python3.4/site-packages/tensorflow/contrib/compiler/xla.py\", line 28, in <module>\n",
                "    from tensorflow.python.estimator import model_fn as model_fn_lib\n",
                "  File \"/usr/local/lib/python3.4/site-packages/tensorflow/python/estimator/model_fn.py\", line 26, in <module>\n",
                "    from tensorflow_estimator.python.estimator import model_fn\n",
                "  File \"/usr/local/lib/python3.4/site-packages/tensorflow_estimator/python/estimator/model_fn.py\", line 27, in <module>\n",
                "    from tensorflow.python.saved_model import model_utils as export_utils\n",
                "ImportError: cannot import name 'model_utils'\n"
            ],
            "output": [],
            "retval": 1,
            "seconds": 2.08
        },
        "tensorflow_v0.11/2_BasicModels/linear_regression.py": {
            "error": [
                "WARNING:tensorflow:From /usr/local/lib/python3.4/site-packages/tensorflow/python/framework/op_def_library.py:263: colocate_with (from tensorflow.python.framework.ops) is deprecated and will be removed in a future version.\n",
                "Instructions for updating:\n",
                "Colocations handled automatically by placer.\n",
                "Traceback (most recent call last):\n",
                "  File \"tensorflow_v0.11/2_BasicModels/linear_regression.py\", line 81, in <module>\n",
                "    pred = tf.add(tf.mul(X, W), b)\n",
                "AttributeError: 'module' object has no attribute 'mul'\n"
            ],
            "output": [],
            "retval": 1,
            "seconds": 1.88
        },
        "tensorflow_v0.11/2_BasicModels/nearest_neighbor.py": {
            "error": [
                "Traceback (most recent call last):\n",
                "  File \"tensorflow_v0.11/2_BasicModels/nearest_neighbor.py\", line 23, in <module>\n",
                "    from tensorflow.examples.tutorials.mnist import input_data\n",
                "  File \"/usr/local/lib/python3.4/site-packages/tensorflow/examples/tutorials/mnist/__init__.py\", line 21, in <module>\n",
                "    from tensorflow.examples.tutorials.mnist import input_data\n",
                "  File \"/usr/local/lib/python3.4/site-packages/tensorflow/examples/tutorials/mnist/input_data.py\", line 30, in <module>\n",
                "    from tensorflow.contrib.learn.python.learn.datasets.mnist import read_data_sets\n",
                "  File \"/usr/local/lib/python3.4/site-packages/tensorflow/contrib/__init__.py\", line 40, in <module>\n",
                "    from tensorflow.contrib import distribute\n",
                "  File \"/usr/local/lib/python3.4/site-packages/tensorflow/contrib/distribute/__init__.py\", line 33, in <module>\n",
                "    from tensorflow.contrib.distribute.python.tpu_strategy import TPUStrategy\n",
                "  File \"/usr/local/lib/python3.4/site-packages/tensorflow/contrib/distribute/python/tpu_strategy.py\", line 27, in <module>\n",
                "    from tensorflow.contrib.tpu.python.ops import tpu_ops\n",
                "  File \"/usr/local/lib/python3.4/site-packages/tensorflow/contrib/tpu/__init__.py\", line 73, in <module>\n",
                "    from tensorflow.contrib.tpu.python.tpu.keras_support import tpu_model as keras_to_tpu_model\n",
                "  File \"/usr/local/lib/python3.4/site-packages/tensorflow/contrib/tpu/python/tpu/keras_support.py\", line 62, in <module>\n",
                "    from tensorflow.contrib.tpu.python.tpu import tpu\n",
                "  File \"/usr/local/lib/python3.4/site-packages/tensorflow/contrib/tpu/python/tpu/tpu.py\", line 24, in <module>\n",
                "    from tensorflow.contrib.compiler import xla\n",
                "  File \"/usr/local/lib/python3.4/site-packages/tensorflow/contrib/compiler/xla.py\", line 28, in <module>\n",
                "    from tensorflow.python.estimator import model_fn as model_fn_lib\n",
                "  File \"/usr/local/lib/python3.4/site-packages/tensorflow/python/estimator/model_fn.py\", line 26, in <module>\n",
                "    from tensorflow_estimator.python.estimator import model_fn\n",
                "  File \"/usr/local/lib/python3.4/site-packages/tensorflow_estimator/python/estimator/model_fn.py\", line 27, in <module>\n",
                "    from tensorflow.python.saved_model import model_utils as export_utils\n",
                "ImportError: cannot import name 'model_utils'\n"
            ],
            "output": [],
            "retval": 1,
            "seconds": 2.02
        },
        "tensorflow_v0.11/3_NeuralNetworks/bidirectional_rnn.py": {
            "error": [
                "Traceback (most recent call last):\n",
                "  File \"tensorflow_v0.11/3_NeuralNetworks/bidirectional_rnn.py\", line 24, in <module>\n",
                "    from tensorflow.examples.tutorials.mnist import input_data\n",
                "  File \"/usr/local/lib/python3.4/site-packages/tensorflow/examples/tutorials/mnist/__init__.py\", line 21, in <module>\n",
                "    from tensorflow.examples.tutorials.mnist import input_data\n",
                "  File \"/usr/local/lib/python3.4/site-packages/tensorflow/examples/tutorials/mnist/input_data.py\", line 30, in <module>\n",
                "    from tensorflow.contrib.learn.python.learn.datasets.mnist import read_data_sets\n",
                "  File \"/usr/local/lib/python3.4/site-packages/tensorflow/contrib/__init__.py\", line 40, in <module>\n",
                "    from tensorflow.contrib import distribute\n",
                "  File \"/usr/local/lib/python3.4/site-packages/tensorflow/contrib/distribute/__init__.py\", line 33, in <module>\n",
                "    from tensorflow.contrib.distribute.python.tpu_strategy import TPUStrategy\n",
                "  File \"/usr/local/lib/python3.4/site-packages/tensorflow/contrib/distribute/python/tpu_strategy.py\", line 27, in <module>\n",
                "    from tensorflow.contrib.tpu.python.ops import tpu_ops\n",
                "  File \"/usr/local/lib/python3.4/site-packages/tensorflow/contrib/tpu/__init__.py\", line 73, in <module>\n",
                "    from tensorflow.contrib.tpu.python.tpu.keras_support import tpu_model as keras_to_tpu_model\n",
                "  File \"/usr/local/lib/python3.4/site-packages/tensorflow/contrib/tpu/python/tpu/keras_support.py\", line 62, in <module>\n",
                "    from tensorflow.contrib.tpu.python.tpu import tpu\n",
                "  File \"/usr/local/lib/python3.4/site-packages/tensorflow/contrib/tpu/python/tpu/tpu.py\", line 24, in <module>\n",
                "    from tensorflow.contrib.compiler import xla\n",
                "  File \"/usr/local/lib/python3.4/site-packages/tensorflow/contrib/compiler/xla.py\", line 28, in <module>\n",
                "    from tensorflow.python.estimator import model_fn as model_fn_lib\n",
                "  File \"/usr/local/lib/python3.4/site-packages/tensorflow/python/estimator/model_fn.py\", line 26, in <module>\n",
                "    from tensorflow_estimator.python.estimator import model_fn\n",
                "  File \"/usr/local/lib/python3.4/site-packages/tensorflow_estimator/python/estimator/model_fn.py\", line 27, in <module>\n",
                "    from tensorflow.python.saved_model import model_utils as export_utils\n",
                "ImportError: cannot import name 'model_utils'\n"
            ],
            "output": [],
            "retval": 1,
            "seconds": 2.11
        },
        "tensorflow_v0.11/3_NeuralNetworks/autoencoder.py": {
            "error": [
                "Traceback (most recent call last):\n",
                "  File \"tensorflow_v0.11/3_NeuralNetworks/autoencoder.py\", line 25, in <module>\n",
                "    from tensorflow.examples.tutorials.mnist import input_data\n",
                "  File \"/usr/local/lib/python3.4/site-packages/tensorflow/examples/tutorials/mnist/__init__.py\", line 21, in <module>\n",
                "    from tensorflow.examples.tutorials.mnist import input_data\n",
                "  File \"/usr/local/lib/python3.4/site-packages/tensorflow/examples/tutorials/mnist/input_data.py\", line 30, in <module>\n",
                "    from tensorflow.contrib.learn.python.learn.datasets.mnist import read_data_sets\n",
                "  File \"/usr/local/lib/python3.4/site-packages/tensorflow/contrib/__init__.py\", line 40, in <module>\n",
                "    from tensorflow.contrib import distribute\n",
                "  File \"/usr/local/lib/python3.4/site-packages/tensorflow/contrib/distribute/__init__.py\", line 33, in <module>\n",
                "    from tensorflow.contrib.distribute.python.tpu_strategy import TPUStrategy\n",
                "  File \"/usr/local/lib/python3.4/site-packages/tensorflow/contrib/distribute/python/tpu_strategy.py\", line 27, in <module>\n",
                "    from tensorflow.contrib.tpu.python.ops import tpu_ops\n",
                "  File \"/usr/local/lib/python3.4/site-packages/tensorflow/contrib/tpu/__init__.py\", line 73, in <module>\n",
                "    from tensorflow.contrib.tpu.python.tpu.keras_support import tpu_model as keras_to_tpu_model\n",
                "  File \"/usr/local/lib/python3.4/site-packages/tensorflow/contrib/tpu/python/tpu/keras_support.py\", line 62, in <module>\n",
                "    from tensorflow.contrib.tpu.python.tpu import tpu\n",
                "  File \"/usr/local/lib/python3.4/site-packages/tensorflow/contrib/tpu/python/tpu/tpu.py\", line 24, in <module>\n",
                "    from tensorflow.contrib.compiler import xla\n",
                "  File \"/usr/local/lib/python3.4/site-packages/tensorflow/contrib/compiler/xla.py\", line 28, in <module>\n",
                "    from tensorflow.python.estimator import model_fn as model_fn_lib\n",
                "  File \"/usr/local/lib/python3.4/site-packages/tensorflow/python/estimator/model_fn.py\", line 26, in <module>\n",
                "    from tensorflow_estimator.python.estimator import model_fn\n",
                "  File \"/usr/local/lib/python3.4/site-packages/tensorflow_estimator/python/estimator/model_fn.py\", line 27, in <module>\n",
                "    from tensorflow.python.saved_model import model_utils as export_utils\n",
                "ImportError: cannot import name 'model_utils'\n"
            ],
            "output": [],
            "retval": 1,
            "seconds": 2.16
        },
        "tensorflow_v0.11/3_NeuralNetworks/recurrent_network.py": {
            "error": [
                "Traceback (most recent call last):\n",
                "  File \"tensorflow_v0.11/3_NeuralNetworks/recurrent_network.py\", line 22, in <module>\n",
                "    from tensorflow.examples.tutorials.mnist import input_data\n",
                "  File \"/usr/local/lib/python3.4/site-packages/tensorflow/examples/tutorials/mnist/__init__.py\", line 21, in <module>\n",
                "    from tensorflow.examples.tutorials.mnist import input_data\n",
                "  File \"/usr/local/lib/python3.4/site-packages/tensorflow/examples/tutorials/mnist/input_data.py\", line 30, in <module>\n",
                "    from tensorflow.contrib.learn.python.learn.datasets.mnist import read_data_sets\n",
                "  File \"/usr/local/lib/python3.4/site-packages/tensorflow/contrib/__init__.py\", line 40, in <module>\n",
                "    from tensorflow.contrib import distribute\n",
                "  File \"/usr/local/lib/python3.4/site-packages/tensorflow/contrib/distribute/__init__.py\", line 33, in <module>\n",
                "    from tensorflow.contrib.distribute.python.tpu_strategy import TPUStrategy\n",
                "  File \"/usr/local/lib/python3.4/site-packages/tensorflow/contrib/distribute/python/tpu_strategy.py\", line 27, in <module>\n",
                "    from tensorflow.contrib.tpu.python.ops import tpu_ops\n",
                "  File \"/usr/local/lib/python3.4/site-packages/tensorflow/contrib/tpu/__init__.py\", line 73, in <module>\n",
                "    from tensorflow.contrib.tpu.python.tpu.keras_support import tpu_model as keras_to_tpu_model\n",
                "  File \"/usr/local/lib/python3.4/site-packages/tensorflow/contrib/tpu/python/tpu/keras_support.py\", line 62, in <module>\n",
                "    from tensorflow.contrib.tpu.python.tpu import tpu\n",
                "  File \"/usr/local/lib/python3.4/site-packages/tensorflow/contrib/tpu/python/tpu/tpu.py\", line 24, in <module>\n",
                "    from tensorflow.contrib.compiler import xla\n",
                "  File \"/usr/local/lib/python3.4/site-packages/tensorflow/contrib/compiler/xla.py\", line 28, in <module>\n",
                "    from tensorflow.python.estimator import model_fn as model_fn_lib\n",
                "  File \"/usr/local/lib/python3.4/site-packages/tensorflow/python/estimator/model_fn.py\", line 26, in <module>\n",
                "    from tensorflow_estimator.python.estimator import model_fn\n",
                "  File \"/usr/local/lib/python3.4/site-packages/tensorflow_estimator/python/estimator/model_fn.py\", line 27, in <module>\n",
                "    from tensorflow.python.saved_model import model_utils as export_utils\n",
                "ImportError: cannot import name 'model_utils'\n"
            ],
            "output": [],
            "retval": 1,
            "seconds": 2.09
        },
        "tensorflow_v0.11/3_NeuralNetworks/dynamic_rnn.py": {
            "error": [
                "WARNING:tensorflow:From /usr/local/lib/python3.4/site-packages/tensorflow/python/framework/op_def_library.py:263: colocate_with (from tensorflow.python.framework.ops) is deprecated and will be removed in a future version.\n",
                "Instructions for updating:\n",
                "Colocations handled automatically by placer.\n",
                "Traceback (most recent call last):\n",
                "  File \"/usr/local/lib/python3.4/site-packages/tensorflow/python/framework/op_def_library.py\", line 511, in _apply_op_helper\n",
                "    preferred_dtype=default_dtype)\n",
                "  File \"/usr/local/lib/python3.4/site-packages/tensorflow/python/framework/ops.py\", line 1175, in internal_convert_to_tensor\n",
                "    ret = conversion_func(value, dtype=dtype, name=name, as_ref=as_ref)\n",
                "  File \"/usr/local/lib/python3.4/site-packages/tensorflow/python/framework/ops.py\", line 977, in _TensorTensorConversionFunction\n",
                "    (dtype.name, t.dtype.name, str(t)))\n",
                "ValueError: Tensor conversion requested dtype int32 for Tensor with dtype float32: 'Tensor(\"Reshape:0\", shape=(?, 1), dtype=float32)'\n",
                "\n",
                "During handling of the above exception, another exception occurred:\n",
                "\n",
                "Traceback (most recent call last):\n",
                "  File \"tensorflow_v0.11/3_NeuralNetworks/dynamic_rnn.py\", line 160, in <module>\n",
                "    pred = dynamicRNN(x, seqlen, weights, biases)\n",
                "  File \"tensorflow_v0.11/3_NeuralNetworks/dynamic_rnn.py\", line 128, in dynamicRNN\n",
                "    x = tf.split(0, seq_max_len, x)\n",
                "  File \"/usr/local/lib/python3.4/site-packages/tensorflow/python/ops/array_ops.py\", line 1508, in split\n",
                "    axis=axis, num_split=num_or_size_splits, value=value, name=name)\n",
                "  File \"/usr/local/lib/python3.4/site-packages/tensorflow/python/ops/gen_array_ops.py\", line 8883, in split\n",
                "    \"Split\", split_dim=axis, value=value, num_split=num_split, name=name)\n",
                "  File \"/usr/local/lib/python3.4/site-packages/tensorflow/python/framework/op_def_library.py\", line 534, in _apply_op_helper\n",
                "    (prefix, dtypes.as_dtype(input_arg.type).name))\n",
                "TypeError: Input 'split_dim' of 'Split' Op has type float32 that does not match expected type of int32.\n"
            ],
            "output": [],
            "retval": 1,
            "seconds": 2.02
        },
        "tensorflow_v0.11/3_NeuralNetworks/multilayer_perceptron.py": {
            "error": [
                "Traceback (most recent call last):\n",
                "  File \"tensorflow_v0.11/3_NeuralNetworks/multilayer_perceptron.py\", line 13, in <module>\n",
                "    from tensorflow.examples.tutorials.mnist import input_data\n",
                "  File \"/usr/local/lib/python3.4/site-packages/tensorflow/examples/tutorials/mnist/__init__.py\", line 21, in <module>\n",
                "    from tensorflow.examples.tutorials.mnist import input_data\n",
                "  File \"/usr/local/lib/python3.4/site-packages/tensorflow/examples/tutorials/mnist/input_data.py\", line 30, in <module>\n",
                "    from tensorflow.contrib.learn.python.learn.datasets.mnist import read_data_sets\n",
                "  File \"/usr/local/lib/python3.4/site-packages/tensorflow/contrib/__init__.py\", line 40, in <module>\n",
                "    from tensorflow.contrib import distribute\n",
                "  File \"/usr/local/lib/python3.4/site-packages/tensorflow/contrib/distribute/__init__.py\", line 33, in <module>\n",
                "    from tensorflow.contrib.distribute.python.tpu_strategy import TPUStrategy\n",
                "  File \"/usr/local/lib/python3.4/site-packages/tensorflow/contrib/distribute/python/tpu_strategy.py\", line 27, in <module>\n",
                "    from tensorflow.contrib.tpu.python.ops import tpu_ops\n",
                "  File \"/usr/local/lib/python3.4/site-packages/tensorflow/contrib/tpu/__init__.py\", line 73, in <module>\n",
                "    from tensorflow.contrib.tpu.python.tpu.keras_support import tpu_model as keras_to_tpu_model\n",
                "  File \"/usr/local/lib/python3.4/site-packages/tensorflow/contrib/tpu/python/tpu/keras_support.py\", line 62, in <module>\n",
                "    from tensorflow.contrib.tpu.python.tpu import tpu\n",
                "  File \"/usr/local/lib/python3.4/site-packages/tensorflow/contrib/tpu/python/tpu/tpu.py\", line 24, in <module>\n",
                "    from tensorflow.contrib.compiler import xla\n",
                "  File \"/usr/local/lib/python3.4/site-packages/tensorflow/contrib/compiler/xla.py\", line 28, in <module>\n",
                "    from tensorflow.python.estimator import model_fn as model_fn_lib\n",
                "  File \"/usr/local/lib/python3.4/site-packages/tensorflow/python/estimator/model_fn.py\", line 26, in <module>\n",
                "    from tensorflow_estimator.python.estimator import model_fn\n",
                "  File \"/usr/local/lib/python3.4/site-packages/tensorflow_estimator/python/estimator/model_fn.py\", line 27, in <module>\n",
                "    from tensorflow.python.saved_model import model_utils as export_utils\n",
                "ImportError: cannot import name 'model_utils'\n"
            ],
            "output": [],
            "retval": 1,
            "seconds": 2.13
        },
        "tensorflow_v0.11/3_NeuralNetworks/convolutional_network.py": {
            "error": [
                "Traceback (most recent call last):\n",
                "  File \"tensorflow_v0.11/3_NeuralNetworks/convolutional_network.py\", line 21, in <module>\n",
                "    from tensorflow.examples.tutorials.mnist import input_data\n",
                "  File \"/usr/local/lib/python3.4/site-packages/tensorflow/examples/tutorials/mnist/__init__.py\", line 21, in <module>\n",
                "    from tensorflow.examples.tutorials.mnist import input_data\n",
                "  File \"/usr/local/lib/python3.4/site-packages/tensorflow/examples/tutorials/mnist/input_data.py\", line 30, in <module>\n",
                "    from tensorflow.contrib.learn.python.learn.datasets.mnist import read_data_sets\n",
                "  File \"/usr/local/lib/python3.4/site-packages/tensorflow/contrib/__init__.py\", line 40, in <module>\n",
                "    from tensorflow.contrib import distribute\n",
                "  File \"/usr/local/lib/python3.4/site-packages/tensorflow/contrib/distribute/__init__.py\", line 33, in <module>\n",
                "    from tensorflow.contrib.distribute.python.tpu_strategy import TPUStrategy\n",
                "  File \"/usr/local/lib/python3.4/site-packages/tensorflow/contrib/distribute/python/tpu_strategy.py\", line 27, in <module>\n",
                "    from tensorflow.contrib.tpu.python.ops import tpu_ops\n",
                "  File \"/usr/local/lib/python3.4/site-packages/tensorflow/contrib/tpu/__init__.py\", line 73, in <module>\n",
                "    from tensorflow.contrib.tpu.python.tpu.keras_support import tpu_model as keras_to_tpu_model\n",
                "  File \"/usr/local/lib/python3.4/site-packages/tensorflow/contrib/tpu/python/tpu/keras_support.py\", line 62, in <module>\n",
                "    from tensorflow.contrib.tpu.python.tpu import tpu\n",
                "  File \"/usr/local/lib/python3.4/site-packages/tensorflow/contrib/tpu/python/tpu/tpu.py\", line 24, in <module>\n",
                "    from tensorflow.contrib.compiler import xla\n",
                "  File \"/usr/local/lib/python3.4/site-packages/tensorflow/contrib/compiler/xla.py\", line 28, in <module>\n",
                "    from tensorflow.python.estimator import model_fn as model_fn_lib\n",
                "  File \"/usr/local/lib/python3.4/site-packages/tensorflow/python/estimator/model_fn.py\", line 26, in <module>\n",
                "    from tensorflow_estimator.python.estimator import model_fn\n",
                "  File \"/usr/local/lib/python3.4/site-packages/tensorflow_estimator/python/estimator/model_fn.py\", line 27, in <module>\n",
                "    from tensorflow.python.saved_model import model_utils as export_utils\n",
                "ImportError: cannot import name 'model_utils'\n"
            ],
            "output": [],
            "retval": 1,
            "seconds": 2.11
        },
        "tensorflow_v1/1_Introduction/basic_eager_api.py": {
            "error": [
                "Traceback (most recent call last):\n",
                "  File \"tensorflow_v1/1_Introduction/basic_eager_api.py\", line 23, in <module>\n",
                "    import tensorflow.contrib.eager as tfe\n",
                "  File \"/usr/local/lib/python3.4/site-packages/tensorflow/contrib/__init__.py\", line 40, in <module>\n",
                "    from tensorflow.contrib import distribute\n",
                "  File \"/usr/local/lib/python3.4/site-packages/tensorflow/contrib/distribute/__init__.py\", line 33, in <module>\n",
                "    from tensorflow.contrib.distribute.python.tpu_strategy import TPUStrategy\n",
                "  File \"/usr/local/lib/python3.4/site-packages/tensorflow/contrib/distribute/python/tpu_strategy.py\", line 27, in <module>\n",
                "    from tensorflow.contrib.tpu.python.ops import tpu_ops\n",
                "  File \"/usr/local/lib/python3.4/site-packages/tensorflow/contrib/tpu/__init__.py\", line 73, in <module>\n",
                "    from tensorflow.contrib.tpu.python.tpu.keras_support import tpu_model as keras_to_tpu_model\n",
                "  File \"/usr/local/lib/python3.4/site-packages/tensorflow/contrib/tpu/python/tpu/keras_support.py\", line 62, in <module>\n",
                "    from tensorflow.contrib.tpu.python.tpu import tpu\n",
                "  File \"/usr/local/lib/python3.4/site-packages/tensorflow/contrib/tpu/python/tpu/tpu.py\", line 24, in <module>\n",
                "    from tensorflow.contrib.compiler import xla\n",
                "  File \"/usr/local/lib/python3.4/site-packages/tensorflow/contrib/compiler/xla.py\", line 28, in <module>\n",
                "    from tensorflow.python.estimator import model_fn as model_fn_lib\n",
                "  File \"/usr/local/lib/python3.4/site-packages/tensorflow/python/estimator/model_fn.py\", line 26, in <module>\n",
                "    from tensorflow_estimator.python.estimator import model_fn\n",
                "  File \"/usr/local/lib/python3.4/site-packages/tensorflow_estimator/python/estimator/model_fn.py\", line 27, in <module>\n",
                "    from tensorflow.python.saved_model import model_utils as export_utils\n",
                "ImportError: cannot import name 'model_utils'\n"
            ],
            "output": [],
            "retval": 1,
            "seconds": 2.08
        },
        "tensorflow_v1/1_Introduction/basic_operations.py": {
            "error": [
                "2021-01-07 02:18:47.613122: I tensorflow/core/platform/cpu_feature_guard.cc:141] Your CPU supports instructions that this TensorFlow binary was not compiled to use: AVX2 FMA\n",
                "2021-01-07 02:18:47.638105: I tensorflow/core/platform/profile_utils/cpu_utils.cc:94] CPU Frequency: 1999965000 Hz\n",
                "2021-01-07 02:18:47.638472: I tensorflow/compiler/xla/service/service.cc:150] XLA service 0x5610e8768c90 executing computations on platform Host. Devices:\n",
                "2021-01-07 02:18:47.638495: I tensorflow/compiler/xla/service/service.cc:158]   StreamExecutor device (0): <undefined>, <undefined>\n"
            ],
            "output": [
                "a=2, b=3\n",
                "Addition with constants: 5\n",
                "Multiplication with constants: 6\n",
                "Addition with variables: 5\n",
                "Multiplication with variables: 6\n",
                "[[12.]]\n"
            ],
            "retval": 0,
            "seconds": 1.91
        },
        "tensorflow_v1/1_Introduction/helloworld.py": {
            "error": [
                "2021-01-07 02:18:49.547419: I tensorflow/core/platform/cpu_feature_guard.cc:141] Your CPU supports instructions that this TensorFlow binary was not compiled to use: AVX2 FMA\n",
                "2021-01-07 02:18:49.570265: I tensorflow/core/platform/profile_utils/cpu_utils.cc:94] CPU Frequency: 1999965000 Hz\n",
                "2021-01-07 02:18:49.570681: I tensorflow/compiler/xla/service/service.cc:150] XLA service 0x55bb87ce9110 executing computations on platform Host. Devices:\n",
                "2021-01-07 02:18:49.570715: I tensorflow/compiler/xla/service/service.cc:158]   StreamExecutor device (0): <undefined>, <undefined>\n"
            ],
            "output": [
                "b'Hello, TensorFlow!'\n"
            ],
            "retval": 0,
            "seconds": 1.93
        },
        "tensorflow_v1/4_Utils/tensorboard_advanced.py": {
            "error": [
                "Traceback (most recent call last):\n",
                "  File \"tensorflow_v1/4_Utils/tensorboard_advanced.py\", line 20, in <module>\n",
                "    from tensorflow.examples.tutorials.mnist import input_data\n",
                "  File \"/usr/local/lib/python3.4/site-packages/tensorflow/examples/tutorials/mnist/__init__.py\", line 21, in <module>\n",
                "    from tensorflow.examples.tutorials.mnist import input_data\n",
                "  File \"/usr/local/lib/python3.4/site-packages/tensorflow/examples/tutorials/mnist/input_data.py\", line 30, in <module>\n",
                "    from tensorflow.contrib.learn.python.learn.datasets.mnist import read_data_sets\n",
                "  File \"/usr/local/lib/python3.4/site-packages/tensorflow/contrib/__init__.py\", line 40, in <module>\n",
                "    from tensorflow.contrib import distribute\n",
                "  File \"/usr/local/lib/python3.4/site-packages/tensorflow/contrib/distribute/__init__.py\", line 33, in <module>\n",
                "    from tensorflow.contrib.distribute.python.tpu_strategy import TPUStrategy\n",
                "  File \"/usr/local/lib/python3.4/site-packages/tensorflow/contrib/distribute/python/tpu_strategy.py\", line 27, in <module>\n",
                "    from tensorflow.contrib.tpu.python.ops import tpu_ops\n",
                "  File \"/usr/local/lib/python3.4/site-packages/tensorflow/contrib/tpu/__init__.py\", line 73, in <module>\n",
                "    from tensorflow.contrib.tpu.python.tpu.keras_support import tpu_model as keras_to_tpu_model\n",
                "  File \"/usr/local/lib/python3.4/site-packages/tensorflow/contrib/tpu/python/tpu/keras_support.py\", line 62, in <module>\n",
                "    from tensorflow.contrib.tpu.python.tpu import tpu\n",
                "  File \"/usr/local/lib/python3.4/site-packages/tensorflow/contrib/tpu/python/tpu/tpu.py\", line 24, in <module>\n",
                "    from tensorflow.contrib.compiler import xla\n",
                "  File \"/usr/local/lib/python3.4/site-packages/tensorflow/contrib/compiler/xla.py\", line 28, in <module>\n",
                "    from tensorflow.python.estimator import model_fn as model_fn_lib\n",
                "  File \"/usr/local/lib/python3.4/site-packages/tensorflow/python/estimator/model_fn.py\", line 26, in <module>\n",
                "    from tensorflow_estimator.python.estimator import model_fn\n",
                "  File \"/usr/local/lib/python3.4/site-packages/tensorflow_estimator/python/estimator/model_fn.py\", line 27, in <module>\n",
                "    from tensorflow.python.saved_model import model_utils as export_utils\n",
                "ImportError: cannot import name 'model_utils'\n"
            ],
            "output": [],
            "retval": 1,
            "seconds": 2.08
        },
        "tensorflow_v1/4_Utils/tensorboard_basic.py": {
            "error": [
                "Traceback (most recent call last):\n",
                "  File \"tensorflow_v1/4_Utils/tensorboard_basic.py\", line 20, in <module>\n",
                "    from tensorflow.examples.tutorials.mnist import input_data\n",
                "  File \"/usr/local/lib/python3.4/site-packages/tensorflow/examples/tutorials/mnist/__init__.py\", line 21, in <module>\n",
                "    from tensorflow.examples.tutorials.mnist import input_data\n",
                "  File \"/usr/local/lib/python3.4/site-packages/tensorflow/examples/tutorials/mnist/input_data.py\", line 30, in <module>\n",
                "    from tensorflow.contrib.learn.python.learn.datasets.mnist import read_data_sets\n",
                "  File \"/usr/local/lib/python3.4/site-packages/tensorflow/contrib/__init__.py\", line 40, in <module>\n",
                "    from tensorflow.contrib import distribute\n",
                "  File \"/usr/local/lib/python3.4/site-packages/tensorflow/contrib/distribute/__init__.py\", line 33, in <module>\n",
                "    from tensorflow.contrib.distribute.python.tpu_strategy import TPUStrategy\n",
                "  File \"/usr/local/lib/python3.4/site-packages/tensorflow/contrib/distribute/python/tpu_strategy.py\", line 27, in <module>\n",
                "    from tensorflow.contrib.tpu.python.ops import tpu_ops\n",
                "  File \"/usr/local/lib/python3.4/site-packages/tensorflow/contrib/tpu/__init__.py\", line 73, in <module>\n",
                "    from tensorflow.contrib.tpu.python.tpu.keras_support import tpu_model as keras_to_tpu_model\n",
                "  File \"/usr/local/lib/python3.4/site-packages/tensorflow/contrib/tpu/python/tpu/keras_support.py\", line 62, in <module>\n",
                "    from tensorflow.contrib.tpu.python.tpu import tpu\n",
                "  File \"/usr/local/lib/python3.4/site-packages/tensorflow/contrib/tpu/python/tpu/tpu.py\", line 24, in <module>\n",
                "    from tensorflow.contrib.compiler import xla\n",
                "  File \"/usr/local/lib/python3.4/site-packages/tensorflow/contrib/compiler/xla.py\", line 28, in <module>\n",
                "    from tensorflow.python.estimator import model_fn as model_fn_lib\n",
                "  File \"/usr/local/lib/python3.4/site-packages/tensorflow/python/estimator/model_fn.py\", line 26, in <module>\n",
                "    from tensorflow_estimator.python.estimator import model_fn\n",
                "  File \"/usr/local/lib/python3.4/site-packages/tensorflow_estimator/python/estimator/model_fn.py\", line 27, in <module>\n",
                "    from tensorflow.python.saved_model import model_utils as export_utils\n",
                "ImportError: cannot import name 'model_utils'\n"
            ],
            "output": [],
            "retval": 1,
            "seconds": 2.07
        },
        "tensorflow_v1/5_DataManagement/build_an_image_dataset.py": {
            "error": [
                "Traceback (most recent call last):\n",
                "  File \"tensorflow_v1/5_DataManagement/build_an_image_dataset.py\", line 74, in read_images\n",
                "    classes = sorted(os.walk(dataset_path).next()[1])\n",
                "AttributeError: 'generator' object has no attribute 'next'\n",
                "\n",
                "During handling of the above exception, another exception occurred:\n",
                "\n",
                "Traceback (most recent call last):\n",
                "  File \"tensorflow_v1/5_DataManagement/build_an_image_dataset.py\", line 133, in <module>\n",
                "    X, Y = read_images(DATASET_PATH, MODE, batch_size)\n",
                "  File \"tensorflow_v1/5_DataManagement/build_an_image_dataset.py\", line 76, in read_images\n",
                "    classes = sorted(os.walk(dataset_path).__next__()[1])\n",
                "StopIteration\n"
            ],
            "output": [],
            "retval": 1,
            "seconds": 1.79
        },
        "tensorflow_v1/5_DataManagement/tensorflow_dataset_api.py": {
            "error": [
                "Traceback (most recent call last):\n",
                "  File \"tensorflow_v1/5_DataManagement/tensorflow_dataset_api.py\", line 20, in <module>\n",
                "    from tensorflow.examples.tutorials.mnist import input_data\n",
                "  File \"/usr/local/lib/python3.4/site-packages/tensorflow/examples/tutorials/mnist/__init__.py\", line 21, in <module>\n",
                "    from tensorflow.examples.tutorials.mnist import input_data\n",
                "  File \"/usr/local/lib/python3.4/site-packages/tensorflow/examples/tutorials/mnist/input_data.py\", line 30, in <module>\n",
                "    from tensorflow.contrib.learn.python.learn.datasets.mnist import read_data_sets\n",
                "  File \"/usr/local/lib/python3.4/site-packages/tensorflow/contrib/__init__.py\", line 40, in <module>\n",
                "    from tensorflow.contrib import distribute\n",
                "  File \"/usr/local/lib/python3.4/site-packages/tensorflow/contrib/distribute/__init__.py\", line 33, in <module>\n",
                "    from tensorflow.contrib.distribute.python.tpu_strategy import TPUStrategy\n",
                "  File \"/usr/local/lib/python3.4/site-packages/tensorflow/contrib/distribute/python/tpu_strategy.py\", line 27, in <module>\n",
                "    from tensorflow.contrib.tpu.python.ops import tpu_ops\n",
                "  File \"/usr/local/lib/python3.4/site-packages/tensorflow/contrib/tpu/__init__.py\", line 73, in <module>\n",
                "    from tensorflow.contrib.tpu.python.tpu.keras_support import tpu_model as keras_to_tpu_model\n",
                "  File \"/usr/local/lib/python3.4/site-packages/tensorflow/contrib/tpu/python/tpu/keras_support.py\", line 62, in <module>\n",
                "    from tensorflow.contrib.tpu.python.tpu import tpu\n",
                "  File \"/usr/local/lib/python3.4/site-packages/tensorflow/contrib/tpu/python/tpu/tpu.py\", line 24, in <module>\n",
                "    from tensorflow.contrib.compiler import xla\n",
                "  File \"/usr/local/lib/python3.4/site-packages/tensorflow/contrib/compiler/xla.py\", line 28, in <module>\n",
                "    from tensorflow.python.estimator import model_fn as model_fn_lib\n",
                "  File \"/usr/local/lib/python3.4/site-packages/tensorflow/python/estimator/model_fn.py\", line 26, in <module>\n",
                "    from tensorflow_estimator.python.estimator import model_fn\n",
                "  File \"/usr/local/lib/python3.4/site-packages/tensorflow_estimator/python/estimator/model_fn.py\", line 27, in <module>\n",
                "    from tensorflow.python.saved_model import model_utils as export_utils\n",
                "ImportError: cannot import name 'model_utils'\n"
            ],
            "output": [],
            "retval": 1,
            "seconds": 2.13
        },
        "tensorflow_v1/2_BasicModels/random_forest.py": {
            "error": [
                "Traceback (most recent call last):\n",
                "  File \"tensorflow_v1/2_BasicModels/random_forest.py\", line 14, in <module>\n",
                "    from tensorflow.contrib.tensor_forest.python import tensor_forest\n",
                "  File \"/usr/local/lib/python3.4/site-packages/tensorflow/contrib/__init__.py\", line 40, in <module>\n",
                "    from tensorflow.contrib import distribute\n",
                "  File \"/usr/local/lib/python3.4/site-packages/tensorflow/contrib/distribute/__init__.py\", line 33, in <module>\n",
                "    from tensorflow.contrib.distribute.python.tpu_strategy import TPUStrategy\n",
                "  File \"/usr/local/lib/python3.4/site-packages/tensorflow/contrib/distribute/python/tpu_strategy.py\", line 27, in <module>\n",
                "    from tensorflow.contrib.tpu.python.ops import tpu_ops\n",
                "  File \"/usr/local/lib/python3.4/site-packages/tensorflow/contrib/tpu/__init__.py\", line 73, in <module>\n",
                "    from tensorflow.contrib.tpu.python.tpu.keras_support import tpu_model as keras_to_tpu_model\n",
                "  File \"/usr/local/lib/python3.4/site-packages/tensorflow/contrib/tpu/python/tpu/keras_support.py\", line 62, in <module>\n",
                "    from tensorflow.contrib.tpu.python.tpu import tpu\n",
                "  File \"/usr/local/lib/python3.4/site-packages/tensorflow/contrib/tpu/python/tpu/tpu.py\", line 24, in <module>\n",
                "    from tensorflow.contrib.compiler import xla\n",
                "  File \"/usr/local/lib/python3.4/site-packages/tensorflow/contrib/compiler/xla.py\", line 28, in <module>\n",
                "    from tensorflow.python.estimator import model_fn as model_fn_lib\n",
                "  File \"/usr/local/lib/python3.4/site-packages/tensorflow/python/estimator/model_fn.py\", line 26, in <module>\n",
                "    from tensorflow_estimator.python.estimator import model_fn\n",
                "  File \"/usr/local/lib/python3.4/site-packages/tensorflow_estimator/python/estimator/model_fn.py\", line 27, in <module>\n",
                "    from tensorflow.python.saved_model import model_utils as export_utils\n",
                "ImportError: cannot import name 'model_utils'\n"
            ],
            "output": [],
            "retval": 1,
            "seconds": 2.12
        },
        "tensorflow_v1/2_BasicModels/gradient_boosted_decision_tree.py": {
            "error": [
                "Traceback (most recent call last):\n",
                "  File \"tensorflow_v1/2_BasicModels/gradient_boosted_decision_tree.py\", line 17, in <module>\n",
                "    from tensorflow.contrib.boosted_trees.estimator_batch.estimator import (\n",
                "  File \"/usr/local/lib/python3.4/site-packages/tensorflow/contrib/__init__.py\", line 40, in <module>\n",
                "    from tensorflow.contrib import distribute\n",
                "  File \"/usr/local/lib/python3.4/site-packages/tensorflow/contrib/distribute/__init__.py\", line 33, in <module>\n",
                "    from tensorflow.contrib.distribute.python.tpu_strategy import TPUStrategy\n",
                "  File \"/usr/local/lib/python3.4/site-packages/tensorflow/contrib/distribute/python/tpu_strategy.py\", line 27, in <module>\n",
                "    from tensorflow.contrib.tpu.python.ops import tpu_ops\n",
                "  File \"/usr/local/lib/python3.4/site-packages/tensorflow/contrib/tpu/__init__.py\", line 73, in <module>\n",
                "    from tensorflow.contrib.tpu.python.tpu.keras_support import tpu_model as keras_to_tpu_model\n",
                "  File \"/usr/local/lib/python3.4/site-packages/tensorflow/contrib/tpu/python/tpu/keras_support.py\", line 62, in <module>\n",
                "    from tensorflow.contrib.tpu.python.tpu import tpu\n",
                "  File \"/usr/local/lib/python3.4/site-packages/tensorflow/contrib/tpu/python/tpu/tpu.py\", line 24, in <module>\n",
                "    from tensorflow.contrib.compiler import xla\n",
                "  File \"/usr/local/lib/python3.4/site-packages/tensorflow/contrib/compiler/xla.py\", line 28, in <module>\n",
                "    from tensorflow.python.estimator import model_fn as model_fn_lib\n",
                "  File \"/usr/local/lib/python3.4/site-packages/tensorflow/python/estimator/model_fn.py\", line 26, in <module>\n",
                "    from tensorflow_estimator.python.estimator import model_fn\n",
                "  File \"/usr/local/lib/python3.4/site-packages/tensorflow_estimator/python/estimator/model_fn.py\", line 27, in <module>\n",
                "    from tensorflow.python.saved_model import model_utils as export_utils\n",
                "ImportError: cannot import name 'model_utils'\n"
            ],
            "output": [],
            "retval": 1,
            "seconds": 2.16
        },
        "tensorflow_v1/2_BasicModels/logistic_regression.py": {
            "error": [
                "Traceback (most recent call last):\n",
                "  File \"tensorflow_v1/2_BasicModels/logistic_regression.py\", line 21, in <module>\n",
                "    from tensorflow.examples.tutorials.mnist import input_data\n",
                "  File \"/usr/local/lib/python3.4/site-packages/tensorflow/examples/tutorials/mnist/__init__.py\", line 21, in <module>\n",
                "    from tensorflow.examples.tutorials.mnist import input_data\n",
                "  File \"/usr/local/lib/python3.4/site-packages/tensorflow/examples/tutorials/mnist/input_data.py\", line 30, in <module>\n",
                "    from tensorflow.contrib.learn.python.learn.datasets.mnist import read_data_sets\n",
                "  File \"/usr/local/lib/python3.4/site-packages/tensorflow/contrib/__init__.py\", line 40, in <module>\n",
                "    from tensorflow.contrib import distribute\n",
                "  File \"/usr/local/lib/python3.4/site-packages/tensorflow/contrib/distribute/__init__.py\", line 33, in <module>\n",
                "    from tensorflow.contrib.distribute.python.tpu_strategy import TPUStrategy\n",
                "  File \"/usr/local/lib/python3.4/site-packages/tensorflow/contrib/distribute/python/tpu_strategy.py\", line 27, in <module>\n",
                "    from tensorflow.contrib.tpu.python.ops import tpu_ops\n",
                "  File \"/usr/local/lib/python3.4/site-packages/tensorflow/contrib/tpu/__init__.py\", line 73, in <module>\n",
                "    from tensorflow.contrib.tpu.python.tpu.keras_support import tpu_model as keras_to_tpu_model\n",
                "  File \"/usr/local/lib/python3.4/site-packages/tensorflow/contrib/tpu/python/tpu/keras_support.py\", line 62, in <module>\n",
                "    from tensorflow.contrib.tpu.python.tpu import tpu\n",
                "  File \"/usr/local/lib/python3.4/site-packages/tensorflow/contrib/tpu/python/tpu/tpu.py\", line 24, in <module>\n",
                "    from tensorflow.contrib.compiler import xla\n",
                "  File \"/usr/local/lib/python3.4/site-packages/tensorflow/contrib/compiler/xla.py\", line 28, in <module>\n",
                "    from tensorflow.python.estimator import model_fn as model_fn_lib\n",
                "  File \"/usr/local/lib/python3.4/site-packages/tensorflow/python/estimator/model_fn.py\", line 26, in <module>\n",
                "    from tensorflow_estimator.python.estimator import model_fn\n",
                "  File \"/usr/local/lib/python3.4/site-packages/tensorflow_estimator/python/estimator/model_fn.py\", line 27, in <module>\n",
                "    from tensorflow.python.saved_model import model_utils as export_utils\n",
                "ImportError: cannot import name 'model_utils'\n"
            ],
            "output": [],
            "retval": 1,
            "seconds": 2.1
        },
        "tensorflow_v1/2_BasicModels/word2vec.py": {
            "error": [
                "Traceback (most recent call last):\n",
                "  File \"tensorflow_v1/2_BasicModels/word2vec.py\", line 58, in <module>\n",
                "    filename, _ = urllib.urlretrieve(url, data_path)\n",
                "AttributeError: 'module' object has no attribute 'urlretrieve'\n"
            ],
            "output": [
                "Downloading the dataset... (It may take some time)\n"
            ],
            "retval": 1,
            "seconds": 1.82
        },
        "tensorflow_v1/2_BasicModels/linear_regression.py": {
            "error": [
                "WARNING:tensorflow:From /usr/local/lib/python3.4/site-packages/tensorflow/python/framework/op_def_library.py:263: colocate_with (from tensorflow.python.framework.ops) is deprecated and will be removed in a future version.\n",
                "Instructions for updating:\n",
                "Colocations handled automatically by placer.\n",
                "WARNING:tensorflow:From /usr/local/lib/python3.4/site-packages/tensorflow/python/ops/math_ops.py:3066: to_int32 (from tensorflow.python.ops.math_ops) is deprecated and will be removed in a future version.\n",
                "Instructions for updating:\n",
                "Use tf.cast instead.\n",
                "2021-01-07 02:19:07.783048: I tensorflow/core/platform/cpu_feature_guard.cc:141] Your CPU supports instructions that this TensorFlow binary was not compiled to use: AVX2 FMA\n",
                "2021-01-07 02:19:07.806300: I tensorflow/core/platform/profile_utils/cpu_utils.cc:94] CPU Frequency: 1999965000 Hz\n",
                "2021-01-07 02:19:07.806686: I tensorflow/compiler/xla/service/service.cc:150] XLA service 0x56375d73c240 executing computations on platform Host. Devices:\n",
                "2021-01-07 02:19:07.806720: I tensorflow/compiler/xla/service/service.cc:158]   StreamExecutor device (0): <undefined>, <undefined>\n"
            ],
            "output": [
                "Epoch: 0050 cost= 0.213137463 W= 0.4558863 b= -0.6825888\n",
                "Epoch: 0100 cost= 0.197407037 W= 0.443617 b= -0.5943239\n",
                "Optimization Finished!\n",
                "Training cost= 0.19740704 W= 0.443617 b= -0.5943239 \n",
                "\n"
            ],
            "retval": 0,
            "seconds": 2.36
        },
        "tensorflow_v1/2_BasicModels/logistic_regression_eager_api.py": {
            "error": [
                "Traceback (most recent call last):\n",
                "  File \"tensorflow_v1/2_BasicModels/logistic_regression_eager_api.py\", line 20, in <module>\n",
                "    tf.enable_eager_execution()\n",
                "  File \"/usr/local/lib/python3.4/site-packages/tensorflow/python/framework/ops.py\", line 5461, in enable_eager_execution\n",
                "    server_def=None)\n",
                "  File \"/usr/local/lib/python3.4/site-packages/tensorflow/python/framework/ops.py\", line 5516, in enable_eager_execution_internal\n",
                "    \"tf.enable_eager_execution must be called at program startup.\")\n",
                "ValueError: tf.enable_eager_execution must be called at program startup.\n"
            ],
            "output": [],
            "retval": 1,
            "seconds": 1.85
        },
        "tensorflow_v1/2_BasicModels/nearest_neighbor.py": {
            "error": [
                "Traceback (most recent call last):\n",
                "  File \"tensorflow_v1/2_BasicModels/nearest_neighbor.py\", line 23, in <module>\n",
                "    from tensorflow.examples.tutorials.mnist import input_data\n",
                "  File \"/usr/local/lib/python3.4/site-packages/tensorflow/examples/tutorials/mnist/__init__.py\", line 21, in <module>\n",
                "    from tensorflow.examples.tutorials.mnist import input_data\n",
                "  File \"/usr/local/lib/python3.4/site-packages/tensorflow/examples/tutorials/mnist/input_data.py\", line 30, in <module>\n",
                "    from tensorflow.contrib.learn.python.learn.datasets.mnist import read_data_sets\n",
                "  File \"/usr/local/lib/python3.4/site-packages/tensorflow/contrib/__init__.py\", line 40, in <module>\n",
                "    from tensorflow.contrib import distribute\n",
                "  File \"/usr/local/lib/python3.4/site-packages/tensorflow/contrib/distribute/__init__.py\", line 33, in <module>\n",
                "    from tensorflow.contrib.distribute.python.tpu_strategy import TPUStrategy\n",
                "  File \"/usr/local/lib/python3.4/site-packages/tensorflow/contrib/distribute/python/tpu_strategy.py\", line 27, in <module>\n",
                "    from tensorflow.contrib.tpu.python.ops import tpu_ops\n",
                "  File \"/usr/local/lib/python3.4/site-packages/tensorflow/contrib/tpu/__init__.py\", line 73, in <module>\n",
                "    from tensorflow.contrib.tpu.python.tpu.keras_support import tpu_model as keras_to_tpu_model\n",
                "  File \"/usr/local/lib/python3.4/site-packages/tensorflow/contrib/tpu/python/tpu/keras_support.py\", line 62, in <module>\n",
                "    from tensorflow.contrib.tpu.python.tpu import tpu\n",
                "  File \"/usr/local/lib/python3.4/site-packages/tensorflow/contrib/tpu/python/tpu/tpu.py\", line 24, in <module>\n",
                "    from tensorflow.contrib.compiler import xla\n",
                "  File \"/usr/local/lib/python3.4/site-packages/tensorflow/contrib/compiler/xla.py\", line 28, in <module>\n",
                "    from tensorflow.python.estimator import model_fn as model_fn_lib\n",
                "  File \"/usr/local/lib/python3.4/site-packages/tensorflow/python/estimator/model_fn.py\", line 26, in <module>\n",
                "    from tensorflow_estimator.python.estimator import model_fn\n",
                "  File \"/usr/local/lib/python3.4/site-packages/tensorflow_estimator/python/estimator/model_fn.py\", line 27, in <module>\n",
                "    from tensorflow.python.saved_model import model_utils as export_utils\n",
                "ImportError: cannot import name 'model_utils'\n"
            ],
            "output": [],
            "retval": 1,
            "seconds": 2.12
        },
        "tensorflow_v1/2_BasicModels/linear_regression_eager_api.py": {
            "error": [
                "Traceback (most recent call last):\n",
                "  File \"tensorflow_v1/2_BasicModels/linear_regression_eager_api.py\", line 21, in <module>\n",
                "    tf.enable_eager_execution()\n",
                "  File \"/usr/local/lib/python3.4/site-packages/tensorflow/python/framework/ops.py\", line 5461, in enable_eager_execution\n",
                "    server_def=None)\n",
                "  File \"/usr/local/lib/python3.4/site-packages/tensorflow/python/framework/ops.py\", line 5516, in enable_eager_execution_internal\n",
                "    \"tf.enable_eager_execution must be called at program startup.\")\n",
                "ValueError: tf.enable_eager_execution must be called at program startup.\n"
            ],
            "output": [],
            "retval": 1,
            "seconds": 1.81
        },
        "tensorflow_v1/2_BasicModels/kmeans.py": {
            "error": [
                "Traceback (most recent call last):\n",
                "  File \"tensorflow_v1/2_BasicModels/kmeans.py\", line 17, in <module>\n",
                "    from tensorflow.contrib.factorization import KMeans\n",
                "  File \"/usr/local/lib/python3.4/site-packages/tensorflow/contrib/__init__.py\", line 40, in <module>\n",
                "    from tensorflow.contrib import distribute\n",
                "  File \"/usr/local/lib/python3.4/site-packages/tensorflow/contrib/distribute/__init__.py\", line 33, in <module>\n",
                "    from tensorflow.contrib.distribute.python.tpu_strategy import TPUStrategy\n",
                "  File \"/usr/local/lib/python3.4/site-packages/tensorflow/contrib/distribute/python/tpu_strategy.py\", line 27, in <module>\n",
                "    from tensorflow.contrib.tpu.python.ops import tpu_ops\n",
                "  File \"/usr/local/lib/python3.4/site-packages/tensorflow/contrib/tpu/__init__.py\", line 73, in <module>\n",
                "    from tensorflow.contrib.tpu.python.tpu.keras_support import tpu_model as keras_to_tpu_model\n",
                "  File \"/usr/local/lib/python3.4/site-packages/tensorflow/contrib/tpu/python/tpu/keras_support.py\", line 62, in <module>\n",
                "    from tensorflow.contrib.tpu.python.tpu import tpu\n",
                "  File \"/usr/local/lib/python3.4/site-packages/tensorflow/contrib/tpu/python/tpu/tpu.py\", line 24, in <module>\n",
                "    from tensorflow.contrib.compiler import xla\n",
                "  File \"/usr/local/lib/python3.4/site-packages/tensorflow/contrib/compiler/xla.py\", line 28, in <module>\n",
                "    from tensorflow.python.estimator import model_fn as model_fn_lib\n",
                "  File \"/usr/local/lib/python3.4/site-packages/tensorflow/python/estimator/model_fn.py\", line 26, in <module>\n",
                "    from tensorflow_estimator.python.estimator import model_fn\n",
                "  File \"/usr/local/lib/python3.4/site-packages/tensorflow_estimator/python/estimator/model_fn.py\", line 27, in <module>\n",
                "    from tensorflow.python.saved_model import model_utils as export_utils\n",
                "ImportError: cannot import name 'model_utils'\n"
            ],
            "output": [],
            "retval": 1,
            "seconds": 2.09
        },
        "tensorflow_v1/6_MultiGPU/multigpu_basics.py": {
            "error": [
                "2021-01-07 02:19:17.885059: I tensorflow/core/platform/cpu_feature_guard.cc:141] Your CPU supports instructions that this TensorFlow binary was not compiled to use: AVX2 FMA\n",
                "2021-01-07 02:19:17.910253: I tensorflow/core/platform/profile_utils/cpu_utils.cc:94] CPU Frequency: 1999965000 Hz\n",
                "2021-01-07 02:19:17.910600: I tensorflow/compiler/xla/service/service.cc:150] XLA service 0x5564307e9390 executing computations on platform Host. Devices:\n",
                "2021-01-07 02:19:17.910624: I tensorflow/compiler/xla/service/service.cc:158]   StreamExecutor device (0): <undefined>, <undefined>\n",
                "2021-01-07 02:19:17.910865: I tensorflow/core/common_runtime/direct_session.cc:317] Device mapping:\n",
                "/job:localhost/replica:0/task:0/device:XLA_CPU:0 -> device: XLA_CPU device\n",
                "\n",
                "2021-01-07 02:19:17.911950: I tensorflow/core/common_runtime/placer.cc:1059] MatMul: (MatMul)/job:localhost/replica:0/task:0/device:CPU:0\n",
                "2021-01-07 02:19:17.911971: I tensorflow/core/common_runtime/placer.cc:1059] MatMul_1: (MatMul)/job:localhost/replica:0/task:0/device:CPU:0\n",
                "2021-01-07 02:19:17.911978: I tensorflow/core/common_runtime/placer.cc:1059] AddN: (AddN)/job:localhost/replica:0/task:0/device:CPU:0\n",
                "2021-01-07 02:19:17.911984: I tensorflow/core/common_runtime/placer.cc:1059] Placeholder: (Placeholder)/job:localhost/replica:0/task:0/device:CPU:0\n",
                "2021-01-07 02:19:17.911990: I tensorflow/core/common_runtime/placer.cc:1059] Placeholder_1: (Placeholder)/job:localhost/replica:0/task:0/device:CPU:0\n",
                "2021-01-07 02:19:17.941385: I tensorflow/core/common_runtime/direct_session.cc:317] Device mapping:\n",
                "/job:localhost/replica:0/task:0/device:XLA_CPU:0 -> device: XLA_CPU device\n",
                "\n",
                "2021-01-07 02:19:17.942028: I tensorflow/core/common_runtime/placer.cc:1059] MatMul: (MatMul)/job:localhost/replica:0/task:0/device:CPU:0\n",
                "2021-01-07 02:19:17.942052: I tensorflow/core/common_runtime/placer.cc:1059] MatMul_1: (MatMul)/job:localhost/replica:0/task:0/device:CPU:0\n",
                "2021-01-07 02:19:17.942058: I tensorflow/core/common_runtime/placer.cc:1059] AddN: (AddN)/job:localhost/replica:0/task:0/device:CPU:0\n",
                "2021-01-07 02:19:17.942063: I tensorflow/core/common_runtime/placer.cc:1059] MatMul_2: (MatMul)/job:localhost/replica:0/task:0/device:CPU:0\n",
                "2021-01-07 02:19:17.942067: I tensorflow/core/common_runtime/placer.cc:1059] MatMul_3: (MatMul)/job:localhost/replica:0/task:0/device:CPU:0\n",
                "2021-01-07 02:19:17.942071: I tensorflow/core/common_runtime/placer.cc:1059] AddN_1: (AddN)/job:localhost/replica:0/task:0/device:CPU:0\n",
                "2021-01-07 02:19:17.942077: I tensorflow/core/common_runtime/placer.cc:1059] Placeholder: (Placeholder)/job:localhost/replica:0/task:0/device:CPU:0\n",
                "2021-01-07 02:19:17.942081: I tensorflow/core/common_runtime/placer.cc:1059] Placeholder_1: (Placeholder)/job:localhost/replica:0/task:0/device:CPU:0\n",
                "2021-01-07 02:19:17.942086: I tensorflow/core/common_runtime/placer.cc:1059] Placeholder_2: (Placeholder)/job:localhost/replica:0/task:0/device:CPU:0\n",
                "2021-01-07 02:19:17.942091: I tensorflow/core/common_runtime/placer.cc:1059] Placeholder_3: (Placeholder)/job:localhost/replica:0/task:0/device:CPU:0\n"
            ],
            "output": [
                "Single CPU computation time: 0:00:00.051411\n",
                "Multi CPU computation time: 0:00:00.023813\n",
                "Device mapping:\n",
                "/job:localhost/replica:0/task:0/device:XLA_CPU:0 -> device: XLA_CPU device\n",
                "MatMul: (MatMul): /job:localhost/replica:0/task:0/device:CPU:0\n",
                "MatMul_1: (MatMul): /job:localhost/replica:0/task:0/device:CPU:0\n",
                "AddN: (AddN): /job:localhost/replica:0/task:0/device:CPU:0\n",
                "Placeholder: (Placeholder): /job:localhost/replica:0/task:0/device:CPU:0\n",
                "Placeholder_1: (Placeholder): /job:localhost/replica:0/task:0/device:CPU:0\n",
                "Device mapping:\n",
                "/job:localhost/replica:0/task:0/device:XLA_CPU:0 -> device: XLA_CPU device\n",
                "MatMul: (MatMul): /job:localhost/replica:0/task:0/device:CPU:0\n",
                "MatMul_1: (MatMul): /job:localhost/replica:0/task:0/device:CPU:0\n",
                "AddN: (AddN): /job:localhost/replica:0/task:0/device:CPU:0\n",
                "MatMul_2: (MatMul): /job:localhost/replica:0/task:0/device:CPU:0\n",
                "MatMul_3: (MatMul): /job:localhost/replica:0/task:0/device:CPU:0\n",
                "AddN_1: (AddN): /job:localhost/replica:0/task:0/device:CPU:0\n",
                "Placeholder: (Placeholder): /job:localhost/replica:0/task:0/device:CPU:0\n",
                "Placeholder_1: (Placeholder): /job:localhost/replica:0/task:0/device:CPU:0\n",
                "Placeholder_2: (Placeholder): /job:localhost/replica:0/task:0/device:CPU:0\n",
                "Placeholder_3: (Placeholder): /job:localhost/replica:0/task:0/device:CPU:0\n"
            ],
            "retval": 0,
            "seconds": 1.94
        },
        "tensorflow_v1/6_MultiGPU/multigpu_cnn.py": {
            "error": [
                "Traceback (most recent call last):\n",
                "  File \"tensorflow_v1/6_MultiGPU/multigpu_cnn.py\", line 28, in <module>\n",
                "    from tensorflow.examples.tutorials.mnist import input_data\n",
                "  File \"/usr/local/lib/python3.4/site-packages/tensorflow/examples/tutorials/mnist/__init__.py\", line 21, in <module>\n",
                "    from tensorflow.examples.tutorials.mnist import input_data\n",
                "  File \"/usr/local/lib/python3.4/site-packages/tensorflow/examples/tutorials/mnist/input_data.py\", line 30, in <module>\n",
                "    from tensorflow.contrib.learn.python.learn.datasets.mnist import read_data_sets\n",
                "  File \"/usr/local/lib/python3.4/site-packages/tensorflow/contrib/__init__.py\", line 40, in <module>\n",
                "    from tensorflow.contrib import distribute\n",
                "  File \"/usr/local/lib/python3.4/site-packages/tensorflow/contrib/distribute/__init__.py\", line 33, in <module>\n",
                "    from tensorflow.contrib.distribute.python.tpu_strategy import TPUStrategy\n",
                "  File \"/usr/local/lib/python3.4/site-packages/tensorflow/contrib/distribute/python/tpu_strategy.py\", line 27, in <module>\n",
                "    from tensorflow.contrib.tpu.python.ops import tpu_ops\n",
                "  File \"/usr/local/lib/python3.4/site-packages/tensorflow/contrib/tpu/__init__.py\", line 73, in <module>\n",
                "    from tensorflow.contrib.tpu.python.tpu.keras_support import tpu_model as keras_to_tpu_model\n",
                "  File \"/usr/local/lib/python3.4/site-packages/tensorflow/contrib/tpu/python/tpu/keras_support.py\", line 62, in <module>\n",
                "    from tensorflow.contrib.tpu.python.tpu import tpu\n",
                "  File \"/usr/local/lib/python3.4/site-packages/tensorflow/contrib/tpu/python/tpu/tpu.py\", line 24, in <module>\n",
                "    from tensorflow.contrib.compiler import xla\n",
                "  File \"/usr/local/lib/python3.4/site-packages/tensorflow/contrib/compiler/xla.py\", line 28, in <module>\n",
                "    from tensorflow.python.estimator import model_fn as model_fn_lib\n",
                "  File \"/usr/local/lib/python3.4/site-packages/tensorflow/python/estimator/model_fn.py\", line 26, in <module>\n",
                "    from tensorflow_estimator.python.estimator import model_fn\n",
                "  File \"/usr/local/lib/python3.4/site-packages/tensorflow_estimator/python/estimator/model_fn.py\", line 27, in <module>\n",
                "    from tensorflow.python.saved_model import model_utils as export_utils\n",
                "ImportError: cannot import name 'model_utils'\n"
            ],
            "output": [],
            "retval": 1,
            "seconds": 2.04
        },
        "tensorflow_v1/3_NeuralNetworks/variational_autoencoder.py": {
            "error": [
                "Traceback (most recent call last):\n",
                "  File \"tensorflow_v1/3_NeuralNetworks/variational_autoencoder.py\", line 35, in <module>\n",
                "    from tensorflow.examples.tutorials.mnist import input_data\n",
                "  File \"/usr/local/lib/python3.4/site-packages/tensorflow/examples/tutorials/mnist/__init__.py\", line 21, in <module>\n",
                "    from tensorflow.examples.tutorials.mnist import input_data\n",
                "  File \"/usr/local/lib/python3.4/site-packages/tensorflow/examples/tutorials/mnist/input_data.py\", line 30, in <module>\n",
                "    from tensorflow.contrib.learn.python.learn.datasets.mnist import read_data_sets\n",
                "  File \"/usr/local/lib/python3.4/site-packages/tensorflow/contrib/__init__.py\", line 40, in <module>\n",
                "    from tensorflow.contrib import distribute\n",
                "  File \"/usr/local/lib/python3.4/site-packages/tensorflow/contrib/distribute/__init__.py\", line 33, in <module>\n",
                "    from tensorflow.contrib.distribute.python.tpu_strategy import TPUStrategy\n",
                "  File \"/usr/local/lib/python3.4/site-packages/tensorflow/contrib/distribute/python/tpu_strategy.py\", line 27, in <module>\n",
                "    from tensorflow.contrib.tpu.python.ops import tpu_ops\n",
                "  File \"/usr/local/lib/python3.4/site-packages/tensorflow/contrib/tpu/__init__.py\", line 73, in <module>\n",
                "    from tensorflow.contrib.tpu.python.tpu.keras_support import tpu_model as keras_to_tpu_model\n",
                "  File \"/usr/local/lib/python3.4/site-packages/tensorflow/contrib/tpu/python/tpu/keras_support.py\", line 62, in <module>\n",
                "    from tensorflow.contrib.tpu.python.tpu import tpu\n",
                "  File \"/usr/local/lib/python3.4/site-packages/tensorflow/contrib/tpu/python/tpu/tpu.py\", line 24, in <module>\n",
                "    from tensorflow.contrib.compiler import xla\n",
                "  File \"/usr/local/lib/python3.4/site-packages/tensorflow/contrib/compiler/xla.py\", line 28, in <module>\n",
                "    from tensorflow.python.estimator import model_fn as model_fn_lib\n",
                "  File \"/usr/local/lib/python3.4/site-packages/tensorflow/python/estimator/model_fn.py\", line 26, in <module>\n",
                "    from tensorflow_estimator.python.estimator import model_fn\n",
                "  File \"/usr/local/lib/python3.4/site-packages/tensorflow_estimator/python/estimator/model_fn.py\", line 27, in <module>\n",
                "    from tensorflow.python.saved_model import model_utils as export_utils\n",
                "ImportError: cannot import name 'model_utils'\n"
            ],
            "output": [],
            "retval": 1,
            "seconds": 1.99
        },
        "tensorflow_v1/3_NeuralNetworks/neural_network_eager_api.py": {
            "error": [
                "Traceback (most recent call last):\n",
                "  File \"tensorflow_v1/3_NeuralNetworks/neural_network_eager_api.py\", line 26, in <module>\n",
                "    tf.enable_eager_execution()\n",
                "  File \"/usr/local/lib/python3.4/site-packages/tensorflow/python/framework/ops.py\", line 5461, in enable_eager_execution\n",
                "    server_def=None)\n",
                "  File \"/usr/local/lib/python3.4/site-packages/tensorflow/python/framework/ops.py\", line 5516, in enable_eager_execution_internal\n",
                "    \"tf.enable_eager_execution must be called at program startup.\")\n",
                "ValueError: tf.enable_eager_execution must be called at program startup.\n"
            ],
            "output": [],
            "retval": 1,
            "seconds": 1.84
        },
        "tensorflow_v1/3_NeuralNetworks/neural_network.py": {
            "error": [
                "Traceback (most recent call last):\n",
                "  File \"tensorflow_v1/3_NeuralNetworks/neural_network.py\", line 20, in <module>\n",
                "    from tensorflow.examples.tutorials.mnist import input_data\n",
                "  File \"/usr/local/lib/python3.4/site-packages/tensorflow/examples/tutorials/mnist/__init__.py\", line 21, in <module>\n",
                "    from tensorflow.examples.tutorials.mnist import input_data\n",
                "  File \"/usr/local/lib/python3.4/site-packages/tensorflow/examples/tutorials/mnist/input_data.py\", line 30, in <module>\n",
                "    from tensorflow.contrib.learn.python.learn.datasets.mnist import read_data_sets\n",
                "  File \"/usr/local/lib/python3.4/site-packages/tensorflow/contrib/__init__.py\", line 40, in <module>\n",
                "    from tensorflow.contrib import distribute\n",
                "  File \"/usr/local/lib/python3.4/site-packages/tensorflow/contrib/distribute/__init__.py\", line 33, in <module>\n",
                "    from tensorflow.contrib.distribute.python.tpu_strategy import TPUStrategy\n",
                "  File \"/usr/local/lib/python3.4/site-packages/tensorflow/contrib/distribute/python/tpu_strategy.py\", line 27, in <module>\n",
                "    from tensorflow.contrib.tpu.python.ops import tpu_ops\n",
                "  File \"/usr/local/lib/python3.4/site-packages/tensorflow/contrib/tpu/__init__.py\", line 73, in <module>\n",
                "    from tensorflow.contrib.tpu.python.tpu.keras_support import tpu_model as keras_to_tpu_model\n",
                "  File \"/usr/local/lib/python3.4/site-packages/tensorflow/contrib/tpu/python/tpu/keras_support.py\", line 62, in <module>\n",
                "    from tensorflow.contrib.tpu.python.tpu import tpu\n",
                "  File \"/usr/local/lib/python3.4/site-packages/tensorflow/contrib/tpu/python/tpu/tpu.py\", line 24, in <module>\n",
                "    from tensorflow.contrib.compiler import xla\n",
                "  File \"/usr/local/lib/python3.4/site-packages/tensorflow/contrib/compiler/xla.py\", line 28, in <module>\n",
                "    from tensorflow.python.estimator import model_fn as model_fn_lib\n",
                "  File \"/usr/local/lib/python3.4/site-packages/tensorflow/python/estimator/model_fn.py\", line 26, in <module>\n",
                "    from tensorflow_estimator.python.estimator import model_fn\n",
                "  File \"/usr/local/lib/python3.4/site-packages/tensorflow_estimator/python/estimator/model_fn.py\", line 27, in <module>\n",
                "    from tensorflow.python.saved_model import model_utils as export_utils\n",
                "ImportError: cannot import name 'model_utils'\n"
            ],
            "output": [],
            "retval": 1,
            "seconds": 2.05
        },
        "tensorflow_v1/3_NeuralNetworks/bidirectional_rnn.py": {
            "error": [
                "Traceback (most recent call last):\n",
                "  File \"tensorflow_v1/3_NeuralNetworks/bidirectional_rnn.py\", line 18, in <module>\n",
                "    from tensorflow.contrib import rnn\n",
                "  File \"/usr/local/lib/python3.4/site-packages/tensorflow/contrib/__init__.py\", line 40, in <module>\n",
                "    from tensorflow.contrib import distribute\n",
                "  File \"/usr/local/lib/python3.4/site-packages/tensorflow/contrib/distribute/__init__.py\", line 33, in <module>\n",
                "    from tensorflow.contrib.distribute.python.tpu_strategy import TPUStrategy\n",
                "  File \"/usr/local/lib/python3.4/site-packages/tensorflow/contrib/distribute/python/tpu_strategy.py\", line 27, in <module>\n",
                "    from tensorflow.contrib.tpu.python.ops import tpu_ops\n",
                "  File \"/usr/local/lib/python3.4/site-packages/tensorflow/contrib/tpu/__init__.py\", line 73, in <module>\n",
                "    from tensorflow.contrib.tpu.python.tpu.keras_support import tpu_model as keras_to_tpu_model\n",
                "  File \"/usr/local/lib/python3.4/site-packages/tensorflow/contrib/tpu/python/tpu/keras_support.py\", line 62, in <module>\n",
                "    from tensorflow.contrib.tpu.python.tpu import tpu\n",
                "  File \"/usr/local/lib/python3.4/site-packages/tensorflow/contrib/tpu/python/tpu/tpu.py\", line 24, in <module>\n",
                "    from tensorflow.contrib.compiler import xla\n",
                "  File \"/usr/local/lib/python3.4/site-packages/tensorflow/contrib/compiler/xla.py\", line 28, in <module>\n",
                "    from tensorflow.python.estimator import model_fn as model_fn_lib\n",
                "  File \"/usr/local/lib/python3.4/site-packages/tensorflow/python/estimator/model_fn.py\", line 26, in <module>\n",
                "    from tensorflow_estimator.python.estimator import model_fn\n",
                "  File \"/usr/local/lib/python3.4/site-packages/tensorflow_estimator/python/estimator/model_fn.py\", line 27, in <module>\n",
                "    from tensorflow.python.saved_model import model_utils as export_utils\n",
                "ImportError: cannot import name 'model_utils'\n"
            ],
            "output": [],
            "retval": 1,
            "seconds": 2.15
        },
        "tensorflow_v1/3_NeuralNetworks/convolutional_network_raw.py": {
            "error": [
                "Traceback (most recent call last):\n",
                "  File \"tensorflow_v1/3_NeuralNetworks/convolutional_network_raw.py\", line 16, in <module>\n",
                "    from tensorflow.examples.tutorials.mnist import input_data\n",
                "  File \"/usr/local/lib/python3.4/site-packages/tensorflow/examples/tutorials/mnist/__init__.py\", line 21, in <module>\n",
                "    from tensorflow.examples.tutorials.mnist import input_data\n",
                "  File \"/usr/local/lib/python3.4/site-packages/tensorflow/examples/tutorials/mnist/input_data.py\", line 30, in <module>\n",
                "    from tensorflow.contrib.learn.python.learn.datasets.mnist import read_data_sets\n",
                "  File \"/usr/local/lib/python3.4/site-packages/tensorflow/contrib/__init__.py\", line 40, in <module>\n",
                "    from tensorflow.contrib import distribute\n",
                "  File \"/usr/local/lib/python3.4/site-packages/tensorflow/contrib/distribute/__init__.py\", line 33, in <module>\n",
                "    from tensorflow.contrib.distribute.python.tpu_strategy import TPUStrategy\n",
                "  File \"/usr/local/lib/python3.4/site-packages/tensorflow/contrib/distribute/python/tpu_strategy.py\", line 27, in <module>\n",
                "    from tensorflow.contrib.tpu.python.ops import tpu_ops\n",
                "  File \"/usr/local/lib/python3.4/site-packages/tensorflow/contrib/tpu/__init__.py\", line 73, in <module>\n",
                "    from tensorflow.contrib.tpu.python.tpu.keras_support import tpu_model as keras_to_tpu_model\n",
                "  File \"/usr/local/lib/python3.4/site-packages/tensorflow/contrib/tpu/python/tpu/keras_support.py\", line 62, in <module>\n",
                "    from tensorflow.contrib.tpu.python.tpu import tpu\n",
                "  File \"/usr/local/lib/python3.4/site-packages/tensorflow/contrib/tpu/python/tpu/tpu.py\", line 24, in <module>\n",
                "    from tensorflow.contrib.compiler import xla\n",
                "  File \"/usr/local/lib/python3.4/site-packages/tensorflow/contrib/compiler/xla.py\", line 28, in <module>\n",
                "    from tensorflow.python.estimator import model_fn as model_fn_lib\n",
                "  File \"/usr/local/lib/python3.4/site-packages/tensorflow/python/estimator/model_fn.py\", line 26, in <module>\n",
                "    from tensorflow_estimator.python.estimator import model_fn\n",
                "  File \"/usr/local/lib/python3.4/site-packages/tensorflow_estimator/python/estimator/model_fn.py\", line 27, in <module>\n",
                "    from tensorflow.python.saved_model import model_utils as export_utils\n",
                "ImportError: cannot import name 'model_utils'\n"
            ],
            "output": [],
            "retval": 1,
            "seconds": 2.08
        },
        "tensorflow_v1/3_NeuralNetworks/autoencoder.py": {
            "error": [
                "Traceback (most recent call last):\n",
                "  File \"tensorflow_v1/3_NeuralNetworks/autoencoder.py\", line 30, in <module>\n",
                "    from tensorflow.examples.tutorials.mnist import input_data\n",
                "  File \"/usr/local/lib/python3.4/site-packages/tensorflow/examples/tutorials/mnist/__init__.py\", line 21, in <module>\n",
                "    from tensorflow.examples.tutorials.mnist import input_data\n",
                "  File \"/usr/local/lib/python3.4/site-packages/tensorflow/examples/tutorials/mnist/input_data.py\", line 30, in <module>\n",
                "    from tensorflow.contrib.learn.python.learn.datasets.mnist import read_data_sets\n",
                "  File \"/usr/local/lib/python3.4/site-packages/tensorflow/contrib/__init__.py\", line 40, in <module>\n",
                "    from tensorflow.contrib import distribute\n",
                "  File \"/usr/local/lib/python3.4/site-packages/tensorflow/contrib/distribute/__init__.py\", line 33, in <module>\n",
                "    from tensorflow.contrib.distribute.python.tpu_strategy import TPUStrategy\n",
                "  File \"/usr/local/lib/python3.4/site-packages/tensorflow/contrib/distribute/python/tpu_strategy.py\", line 27, in <module>\n",
                "    from tensorflow.contrib.tpu.python.ops import tpu_ops\n",
                "  File \"/usr/local/lib/python3.4/site-packages/tensorflow/contrib/tpu/__init__.py\", line 73, in <module>\n",
                "    from tensorflow.contrib.tpu.python.tpu.keras_support import tpu_model as keras_to_tpu_model\n",
                "  File \"/usr/local/lib/python3.4/site-packages/tensorflow/contrib/tpu/python/tpu/keras_support.py\", line 62, in <module>\n",
                "    from tensorflow.contrib.tpu.python.tpu import tpu\n",
                "  File \"/usr/local/lib/python3.4/site-packages/tensorflow/contrib/tpu/python/tpu/tpu.py\", line 24, in <module>\n",
                "    from tensorflow.contrib.compiler import xla\n",
                "  File \"/usr/local/lib/python3.4/site-packages/tensorflow/contrib/compiler/xla.py\", line 28, in <module>\n",
                "    from tensorflow.python.estimator import model_fn as model_fn_lib\n",
                "  File \"/usr/local/lib/python3.4/site-packages/tensorflow/python/estimator/model_fn.py\", line 26, in <module>\n",
                "    from tensorflow_estimator.python.estimator import model_fn\n",
                "  File \"/usr/local/lib/python3.4/site-packages/tensorflow_estimator/python/estimator/model_fn.py\", line 27, in <module>\n",
                "    from tensorflow.python.saved_model import model_utils as export_utils\n",
                "ImportError: cannot import name 'model_utils'\n"
            ],
            "output": [],
            "retval": 1,
            "seconds": 2.11
        },
        "tensorflow_v1/3_NeuralNetworks/gan.py": {
            "error": [
                "Traceback (most recent call last):\n",
                "  File \"tensorflow_v1/3_NeuralNetworks/gan.py\", line 35, in <module>\n",
                "    from tensorflow.examples.tutorials.mnist import input_data\n",
                "  File \"/usr/local/lib/python3.4/site-packages/tensorflow/examples/tutorials/mnist/__init__.py\", line 21, in <module>\n",
                "    from tensorflow.examples.tutorials.mnist import input_data\n",
                "  File \"/usr/local/lib/python3.4/site-packages/tensorflow/examples/tutorials/mnist/input_data.py\", line 30, in <module>\n",
                "    from tensorflow.contrib.learn.python.learn.datasets.mnist import read_data_sets\n",
                "  File \"/usr/local/lib/python3.4/site-packages/tensorflow/contrib/__init__.py\", line 40, in <module>\n",
                "    from tensorflow.contrib import distribute\n",
                "  File \"/usr/local/lib/python3.4/site-packages/tensorflow/contrib/distribute/__init__.py\", line 33, in <module>\n",
                "    from tensorflow.contrib.distribute.python.tpu_strategy import TPUStrategy\n",
                "  File \"/usr/local/lib/python3.4/site-packages/tensorflow/contrib/distribute/python/tpu_strategy.py\", line 27, in <module>\n",
                "    from tensorflow.contrib.tpu.python.ops import tpu_ops\n",
                "  File \"/usr/local/lib/python3.4/site-packages/tensorflow/contrib/tpu/__init__.py\", line 73, in <module>\n",
                "    from tensorflow.contrib.tpu.python.tpu.keras_support import tpu_model as keras_to_tpu_model\n",
                "  File \"/usr/local/lib/python3.4/site-packages/tensorflow/contrib/tpu/python/tpu/keras_support.py\", line 62, in <module>\n",
                "    from tensorflow.contrib.tpu.python.tpu import tpu\n",
                "  File \"/usr/local/lib/python3.4/site-packages/tensorflow/contrib/tpu/python/tpu/tpu.py\", line 24, in <module>\n",
                "    from tensorflow.contrib.compiler import xla\n",
                "  File \"/usr/local/lib/python3.4/site-packages/tensorflow/contrib/compiler/xla.py\", line 28, in <module>\n",
                "    from tensorflow.python.estimator import model_fn as model_fn_lib\n",
                "  File \"/usr/local/lib/python3.4/site-packages/tensorflow/python/estimator/model_fn.py\", line 26, in <module>\n",
                "    from tensorflow_estimator.python.estimator import model_fn\n",
                "  File \"/usr/local/lib/python3.4/site-packages/tensorflow_estimator/python/estimator/model_fn.py\", line 27, in <module>\n",
                "    from tensorflow.python.saved_model import model_utils as export_utils\n",
                "ImportError: cannot import name 'model_utils'\n"
            ],
            "output": [],
            "retval": 1,
            "seconds": 2.13
        },
        "tensorflow_v1/3_NeuralNetworks/recurrent_network.py": {
            "error": [
                "Traceback (most recent call last):\n",
                "  File \"tensorflow_v1/3_NeuralNetworks/recurrent_network.py\", line 17, in <module>\n",
                "    from tensorflow.contrib import rnn\n",
                "  File \"/usr/local/lib/python3.4/site-packages/tensorflow/contrib/__init__.py\", line 40, in <module>\n",
                "    from tensorflow.contrib import distribute\n",
                "  File \"/usr/local/lib/python3.4/site-packages/tensorflow/contrib/distribute/__init__.py\", line 33, in <module>\n",
                "    from tensorflow.contrib.distribute.python.tpu_strategy import TPUStrategy\n",
                "  File \"/usr/local/lib/python3.4/site-packages/tensorflow/contrib/distribute/python/tpu_strategy.py\", line 27, in <module>\n",
                "    from tensorflow.contrib.tpu.python.ops import tpu_ops\n",
                "  File \"/usr/local/lib/python3.4/site-packages/tensorflow/contrib/tpu/__init__.py\", line 73, in <module>\n",
                "    from tensorflow.contrib.tpu.python.tpu.keras_support import tpu_model as keras_to_tpu_model\n",
                "  File \"/usr/local/lib/python3.4/site-packages/tensorflow/contrib/tpu/python/tpu/keras_support.py\", line 62, in <module>\n",
                "    from tensorflow.contrib.tpu.python.tpu import tpu\n",
                "  File \"/usr/local/lib/python3.4/site-packages/tensorflow/contrib/tpu/python/tpu/tpu.py\", line 24, in <module>\n",
                "    from tensorflow.contrib.compiler import xla\n",
                "  File \"/usr/local/lib/python3.4/site-packages/tensorflow/contrib/compiler/xla.py\", line 28, in <module>\n",
                "    from tensorflow.python.estimator import model_fn as model_fn_lib\n",
                "  File \"/usr/local/lib/python3.4/site-packages/tensorflow/python/estimator/model_fn.py\", line 26, in <module>\n",
                "    from tensorflow_estimator.python.estimator import model_fn\n",
                "  File \"/usr/local/lib/python3.4/site-packages/tensorflow_estimator/python/estimator/model_fn.py\", line 27, in <module>\n",
                "    from tensorflow.python.saved_model import model_utils as export_utils\n",
                "ImportError: cannot import name 'model_utils'\n"
            ],
            "output": [],
            "retval": 1,
            "seconds": 2.16
        },
        "tensorflow_v1/3_NeuralNetworks/neural_network_raw.py": {
            "error": [
                "Traceback (most recent call last):\n",
                "  File \"tensorflow_v1/3_NeuralNetworks/neural_network_raw.py\", line 17, in <module>\n",
                "    from tensorflow.examples.tutorials.mnist import input_data\n",
                "  File \"/usr/local/lib/python3.4/site-packages/tensorflow/examples/tutorials/mnist/__init__.py\", line 21, in <module>\n",
                "    from tensorflow.examples.tutorials.mnist import input_data\n",
                "  File \"/usr/local/lib/python3.4/site-packages/tensorflow/examples/tutorials/mnist/input_data.py\", line 30, in <module>\n",
                "    from tensorflow.contrib.learn.python.learn.datasets.mnist import read_data_sets\n",
                "  File \"/usr/local/lib/python3.4/site-packages/tensorflow/contrib/__init__.py\", line 40, in <module>\n",
                "    from tensorflow.contrib import distribute\n",
                "  File \"/usr/local/lib/python3.4/site-packages/tensorflow/contrib/distribute/__init__.py\", line 33, in <module>\n",
                "    from tensorflow.contrib.distribute.python.tpu_strategy import TPUStrategy\n",
                "  File \"/usr/local/lib/python3.4/site-packages/tensorflow/contrib/distribute/python/tpu_strategy.py\", line 27, in <module>\n",
                "    from tensorflow.contrib.tpu.python.ops import tpu_ops\n",
                "  File \"/usr/local/lib/python3.4/site-packages/tensorflow/contrib/tpu/__init__.py\", line 73, in <module>\n",
                "    from tensorflow.contrib.tpu.python.tpu.keras_support import tpu_model as keras_to_tpu_model\n",
                "  File \"/usr/local/lib/python3.4/site-packages/tensorflow/contrib/tpu/python/tpu/keras_support.py\", line 62, in <module>\n",
                "    from tensorflow.contrib.tpu.python.tpu import tpu\n",
                "  File \"/usr/local/lib/python3.4/site-packages/tensorflow/contrib/tpu/python/tpu/tpu.py\", line 24, in <module>\n",
                "    from tensorflow.contrib.compiler import xla\n",
                "  File \"/usr/local/lib/python3.4/site-packages/tensorflow/contrib/compiler/xla.py\", line 28, in <module>\n",
                "    from tensorflow.python.estimator import model_fn as model_fn_lib\n",
                "  File \"/usr/local/lib/python3.4/site-packages/tensorflow/python/estimator/model_fn.py\", line 26, in <module>\n",
                "    from tensorflow_estimator.python.estimator import model_fn\n",
                "  File \"/usr/local/lib/python3.4/site-packages/tensorflow_estimator/python/estimator/model_fn.py\", line 27, in <module>\n",
                "    from tensorflow.python.saved_model import model_utils as export_utils\n",
                "ImportError: cannot import name 'model_utils'\n"
            ],
            "output": [],
            "retval": 1,
            "seconds": 2.07
        },
        "tensorflow_v1/3_NeuralNetworks/multilayer_perceptron.py": {
            "error": [
                "Traceback (most recent call last):\n",
                "  File \"tensorflow_v1/3_NeuralNetworks/multilayer_perceptron.py\", line 24, in <module>\n",
                "    from tensorflow.examples.tutorials.mnist import input_data\n",
                "  File \"/usr/local/lib/python3.4/site-packages/tensorflow/examples/tutorials/mnist/__init__.py\", line 21, in <module>\n",
                "    from tensorflow.examples.tutorials.mnist import input_data\n",
                "  File \"/usr/local/lib/python3.4/site-packages/tensorflow/examples/tutorials/mnist/input_data.py\", line 30, in <module>\n",
                "    from tensorflow.contrib.learn.python.learn.datasets.mnist import read_data_sets\n",
                "  File \"/usr/local/lib/python3.4/site-packages/tensorflow/contrib/__init__.py\", line 40, in <module>\n",
                "    from tensorflow.contrib import distribute\n",
                "  File \"/usr/local/lib/python3.4/site-packages/tensorflow/contrib/distribute/__init__.py\", line 33, in <module>\n",
                "    from tensorflow.contrib.distribute.python.tpu_strategy import TPUStrategy\n",
                "  File \"/usr/local/lib/python3.4/site-packages/tensorflow/contrib/distribute/python/tpu_strategy.py\", line 27, in <module>\n",
                "    from tensorflow.contrib.tpu.python.ops import tpu_ops\n",
                "  File \"/usr/local/lib/python3.4/site-packages/tensorflow/contrib/tpu/__init__.py\", line 73, in <module>\n",
                "    from tensorflow.contrib.tpu.python.tpu.keras_support import tpu_model as keras_to_tpu_model\n",
                "  File \"/usr/local/lib/python3.4/site-packages/tensorflow/contrib/tpu/python/tpu/keras_support.py\", line 62, in <module>\n",
                "    from tensorflow.contrib.tpu.python.tpu import tpu\n",
                "  File \"/usr/local/lib/python3.4/site-packages/tensorflow/contrib/tpu/python/tpu/tpu.py\", line 24, in <module>\n",
                "    from tensorflow.contrib.compiler import xla\n",
                "  File \"/usr/local/lib/python3.4/site-packages/tensorflow/contrib/compiler/xla.py\", line 28, in <module>\n",
                "    from tensorflow.python.estimator import model_fn as model_fn_lib\n",
                "  File \"/usr/local/lib/python3.4/site-packages/tensorflow/python/estimator/model_fn.py\", line 26, in <module>\n",
                "    from tensorflow_estimator.python.estimator import model_fn\n",
                "  File \"/usr/local/lib/python3.4/site-packages/tensorflow_estimator/python/estimator/model_fn.py\", line 27, in <module>\n",
                "    from tensorflow.python.saved_model import model_utils as export_utils\n",
                "ImportError: cannot import name 'model_utils'\n"
            ],
            "output": [],
            "retval": 1,
            "seconds": 2.12
        },
        "tensorflow_v1/3_NeuralNetworks/convolutional_network.py": {
            "error": [
                "Traceback (most recent call last):\n",
                "  File \"tensorflow_v1/3_NeuralNetworks/convolutional_network.py\", line 16, in <module>\n",
                "    from tensorflow.examples.tutorials.mnist import input_data\n",
                "  File \"/usr/local/lib/python3.4/site-packages/tensorflow/examples/tutorials/mnist/__init__.py\", line 21, in <module>\n",
                "    from tensorflow.examples.tutorials.mnist import input_data\n",
                "  File \"/usr/local/lib/python3.4/site-packages/tensorflow/examples/tutorials/mnist/input_data.py\", line 30, in <module>\n",
                "    from tensorflow.contrib.learn.python.learn.datasets.mnist import read_data_sets\n",
                "  File \"/usr/local/lib/python3.4/site-packages/tensorflow/contrib/__init__.py\", line 40, in <module>\n",
                "    from tensorflow.contrib import distribute\n",
                "  File \"/usr/local/lib/python3.4/site-packages/tensorflow/contrib/distribute/__init__.py\", line 33, in <module>\n",
                "    from tensorflow.contrib.distribute.python.tpu_strategy import TPUStrategy\n",
                "  File \"/usr/local/lib/python3.4/site-packages/tensorflow/contrib/distribute/python/tpu_strategy.py\", line 27, in <module>\n",
                "    from tensorflow.contrib.tpu.python.ops import tpu_ops\n",
                "  File \"/usr/local/lib/python3.4/site-packages/tensorflow/contrib/tpu/__init__.py\", line 73, in <module>\n",
                "    from tensorflow.contrib.tpu.python.tpu.keras_support import tpu_model as keras_to_tpu_model\n",
                "  File \"/usr/local/lib/python3.4/site-packages/tensorflow/contrib/tpu/python/tpu/keras_support.py\", line 62, in <module>\n",
                "    from tensorflow.contrib.tpu.python.tpu import tpu\n",
                "  File \"/usr/local/lib/python3.4/site-packages/tensorflow/contrib/tpu/python/tpu/tpu.py\", line 24, in <module>\n",
                "    from tensorflow.contrib.compiler import xla\n",
                "  File \"/usr/local/lib/python3.4/site-packages/tensorflow/contrib/compiler/xla.py\", line 28, in <module>\n",
                "    from tensorflow.python.estimator import model_fn as model_fn_lib\n",
                "  File \"/usr/local/lib/python3.4/site-packages/tensorflow/python/estimator/model_fn.py\", line 26, in <module>\n",
                "    from tensorflow_estimator.python.estimator import model_fn\n",
                "  File \"/usr/local/lib/python3.4/site-packages/tensorflow_estimator/python/estimator/model_fn.py\", line 27, in <module>\n",
                "    from tensorflow.python.saved_model import model_utils as export_utils\n",
                "ImportError: cannot import name 'model_utils'\n"
            ],
            "output": [],
            "retval": 1,
            "seconds": 2.03
        }
    },
    "requirements.txt": [
        "absl-py==0.11.0\n",
        "astor==0.8.1\n",
        "gast==0.4.0\n",
        "grpcio==1.34.0\n",
        "h5py==2.10.0\n",
        "Keras-Applications==1.0.8\n",
        "Keras-Preprocessing==1.1.2\n",
        "Markdown==3.0.1\n",
        "numpy==1.16.6\n",
        "protobuf==3.14.0\n",
        "six==1.15.0\n",
        "tensorboard==1.12.2\n",
        "tensorflow==1.13.0rc0\n",
        "tensorflow-estimator==2.4.0\n",
        "termcolor==1.1.0\n",
        "Werkzeug==0.16.1\n"
    ]
}